Workbook

Sheet Notes
A1: DEP | B1: compound revisionary bonus
A3: Products Covered in Calc 2
A4: DEP
A5: SEP
A6: END
A7: CSR
A8: RBC
A9: CPF
A10: CPH

Sheet Rate Table
A1: CSR High SA Additions %
A2: Sum Assured / Policy Term (Yrs.) | B2: 10 | C2: 13 | D2: 16 | E2: 19 | F2: 22
B3: 2 | C3: 3 | D3: 4 | E3: 5 | F3: 6
A4: 0 | B4: 0 | C4: 0 | D4: 0 | E4: 0 | F4: 0
A5: 250000 | B5: 0.04 | C5: 0.06 | D5: 0.08 | E5: 0.1 | F5: 0.12
A6: 500000 | B6: 0.08 | C6: 0.12 | D6: 0.16 | E6: 0.2 | F6: 0.24
A8: RBC Terminal Bonus %
A9: Policy Years / Policy Term (Yrs.) | B9: 10 | C9: 11 | D9: 12 | E9: 13 | F9: 14 | G9: 15
B10: 2 | C10: 3 | D10: 4 | E10: 5 | F10: 6 | G10: 7
A11: 10 | B11: 0.176 | C11: 0.2222 | D11: 0.2796 | E11: 0.3484 | F11: 0.4312 | G11: 0.5355
A12: 11 | B12: 0 | C12: 0.2222 | D12: 0.2796 | E12: 0.3484 | F12: 0.4312 | G12: 0.5355
A13: 12 | B13: 0 | C13: 0 | D13: 0.2796 | E13: 0.3484 | F13: 0.4312 | G13: 0.5355
A15: CPF and CPH (Payout Option)
A16: Sum Assured / Policy Term (Years) | B16: POLICY PAYOUT TYPE | C16: High Sum Assured %
C17: At Maturity | D17: 2nd year | E17: 3rd Year | F17: 4th Year | G17: 5th Year
A18: Self Starter | B18: SS | C18: (100%*BSA)+ GA+GMA | D18: - | E18: - | F18: - | G18: -
A19: Post Graduation Degree | B19: PG | C19: (50%*BSA) +GA | D19: (50%*BSA+ GMA) * MDF | E19: - | F19: - | G19: -
A20: Professional Degree | B20: PD | C20: (25%*BSA) +GA | D20: 25%*BSA | E20: 25%*BSA | F20: (25%*BSA+ GMA) * MDF | G20: -
A21: Career Starter | B21: CS | C21: (20%*BSA)+ GA | D21: 20%*BSA | E21: 20%*BSA | F21: 20%*BSA | G21: 20%*BSA
A23: 5.2 The Maturity Deferment Factor (MDF) depends on the policy term and payout option selected at inception of the Policy. MDF are calculated at 6.25%p.a., are given below
A24: Policy Term/ Payout Option | C24: Post Graduation Degree | D24: Professional Degree | E24: Career Starter
A25: 9 | C25: 1.0625 | D25: 1.3201 | E25: 1.502
A26: 10 | C26: 1.0625 | D26: 1.3148 | E26: 1.4906
A27: 11 | C27: 1.0625 | D27: 1.3098 | E27: 1.4803
A28: 12 | C28: 1.0625 | D28: 1.3053 | E28: 1.471
A29: 13 | C29: 1.0625 | D29: 1.3012 | E29: 1.4624
A30: 14 | C30: 1.0625 | D30: 1.2973 | E30: 1.4546
A31: 15 | C31: 1.0625 | D31: 1.2938 | E31: 1.4474
A32: 16 | C32: 1.0625 | D32: 1.2905 | E32: 1.4407
A33: 17 | C33: 1.0625 | D33: 1.2874 | E33: 1.4346
A34: 18 | C34: 1.0625 | D34: 1.2845 | E34: 1.4289
A35: 19 | C35: 1.0625 | D35: 1.2818 | E35: 1.4235
A36: 20 | C36: 1.0625 | D36: 1.2793 | E36: 1.4186
A39: CSR (as per Policy)
A40: Policy Term/ Policy Duration | B40: 4 | C40: 7 | D40: 10 | E40: 13 | F40: 16 | G40: 19
A41: 10 | B41: 0.1 | C41: 0.15
A42: 13 | B42: 0.1 | C42: 0.15 | D42: 0.2
A43: 16 | B43: 0.1 | C43: 0.15 | D43: 0.2 | E43: 0.25
A44: 19 | B44: 0.1 | C44: 0.15 | D44: 0.2 | E44: 0.25 | F44: 0.3
A45: 22 | B45: 0.1 | C45: 0.15 | D45: 0.2 | E45: 0.25 | F45: 0.3 | G45: 0.35
...

Sheet MAINCPF CPH DEP SEP END RBC CSR
Z1: x | AH1: x | BL1: to update >>>> | BM1: 46112 | BN1: 0.0825
A2: Dummypol | B2: STATUS | C2: LE_LP_AMT | D2: LE_ME | E2: LE_RY | F2: LE_SI | G2: LE_IM | H2: LE_PA | I2: LE_BT | J2: LE_LY | K2: LE_FE | L2: LE_GM | M2: LN_LO_AMT | N2: LN_LA_AMT | O2: LN_LI_AMT | P2: LE_MC | Q2: LP_S | R2: LP_MS | S2: LE_SB | T2: ASGNNUM | U2: NATLTY | V2: ISSDATE | W2: FIRSTISSDT | X2: PREMIUM01 | Y2: SA | Z2: CNTTYPE | AA2: CATEGORY | AB2: PROD_NAME | AC2: RISK TERM | AD2: PREM TERM | AE2: FREQUENCY | AF2: RCDDATE | AG2: PAIDTODATE | AH2: RISKCESDTE | AI2: PREMCESDTE | AJ2: CLTDOB | AK2: CLTDOD | AL2: ZPANVAL | AM2: ANP_PREMIUM | AN2: STMPDTYAMT | AO2: INSTPREM_GST | AP2: INSTPREM_WITH_GST | AQ2: INSTPREM_WITHOUT_GST | AR2: PLAN_COMPONENT | AS2: COMPONENT_DESC | AT2: ORIGINAL_SA | AU2: ASSIGNEE FLAG | AV2: LITIGATION FLAG | AW2: CURRENT_SA | AX2: ACCUMLATION ACCOUNT BALANCE | AY2: POLICY PAYOUT TYPE | AZ2: ADDITIONAL_ACCUMLATION_ACC_BAL | BA2: AGE LAST BDAY | BB2: BASE_PREMIUM_AMT | BC2: X_LOADED_PREM_AMT | BD2: MODAL_FACTOR | BF2: Status | BG2: Policy Year | BH2: PPT * Freq | BI2: Prem Paid * Freq | BJ2: Paidup Factor | BK2: Annualised premium CSR, END | BL2: Updated SA | BM2: For Current Month Accrued Loan Interest | BN2: Updated LN_LA | BO2: Premium Paid Years | BP2: Lapsed Death Case | BQ2: Policy Inforce Tenure for CPF and CPH | BR2: Benefit Calculator Option basis policy payout option (Applicable for CPF & CPH) | BS2: GA (Applicable for CPF & CPH) | BT2: GMA (Applicable for CPF & CPH) | BU2: Base Benefit (Applicable for CPF & CPH) | BV2: Maturity Benefit TOTAL (CPH & CPF) | BW2: Guaranteed Additions (Applicable for RBC) | BX2: Terminal Bonus (Applicable for RBC) | BY2: Rev. Bonus for RBC | BZ2: Maturity Benefit RBC | CA2: Rev. Bonus for DEP | CB2: Maturity Benefit DEP | CC2: SA Due or Rev. Bonus Due SEP | CD2: Maturity Benefit or Rev. Bonus Amount for SEP | CE2: Rev. Bonus CSR | CF2: High SA Additions Amt (Applicable for CSR) | CG2: Maturity Benefit CSR | CH2: CSR SB Paid | CI2: 100.1% CSR | CJ2: Rev. Bonus for END (1) (LE_RY) | CK2: 100.1 condition bonus (2)(LE_SI) | CL2: Maturity Benefit END | CM2: Benefit Payable - 100.1% of TPP (Applicable for End) | CX2: Total Maturity Benefit (inclusive of Rev. Bonus wherever applicable)
A3: test1010736 | B3: IF | C3: -154413 | E3: -68913.29 | F3: -2755 | Q3: -0.86 | S3: 2755 | U3: IND | V3: 01APR2005:00:00:00 | W3: 38443 | X3: 7038 | Y3: 300000 | Z3: DEP | AA3: TRADITIONAL | AB3: Endowment Plan (Regular) | AC3: 21 | AD3: 21 | AE3: 1 | AF3: 38443 | AG3: 46113 | AH3: 46113 | AI3: 46113 | AJ3: 24601 | AM3: 0 | AO3: 0 | AP3: 0 | AQ3: 0 | AR3: DEP1 | AS3: Endowment Plan (Regular) | AT3: 150000 | AU3: NO | AW3: 150000 | BA3: 59 | BB3: 7038 | BC3: 231 | BF3: =B3 | BG3: =DATEDIF(AF3,AH3,"Y") | BH3: =AD3*AE3 | BI3: =ROUND((AG3-AF3)/365*AE3,0) | BJ3: =BI3/BH3 | BK3: {=IF(Z3="CSR",_xlfn.IFS(AE3=1,BB3,AE3=2,BB3/0.52,AE3=4,BB3/0.265,AE3=12,BB3/0.0834),IF(Z3="END",_xlfn.IFS(AE3=1,BB3,AE3=2,BB3/0.51,AE3=4,BB3/0.26,AE3=12,BB3/0.0834),0))} | BL3: =IF(BF3="IF",AT3,IF(BF3="PU",AT3*BI3/BH3,IF(BF3="PM",AT3*BI3/BH3,""))) | BM3: =IF(AH3 <= $BM$1,0,(M3+ N3)*((1 + $BN$1)^((AH3-$BM$1)/365)-1)) | BN3: =N3+BM3 | BO3: =ROUNDDOWN(DATEDIF(AF3,AG3,"Y"),0) | BP3: =IF(B3<>"DH","NA",IF(AND(BO3<3,AG3+IF(AE3<>12,30,15)<AK3),"Lapsed Death",IF(AG3+IF(AE3<>12,30,15)>=AK3,"Inforce Death","Paidup Death"))) | BQ3: =ROUND((AG3-AF3)/365,0) | BR3: =IF(OR(Z3="CPF",Z3="CPH"),VLOOKUP(AY3,'Rate Table'!$B$16:$G$21,2,FALSE),0) | BS3: =IF(OR(Z3="CPF", Z3="CPH"),IF(BF3="IF",2%*AT3*AC3,IF(BF3="PU",2%*AT3*BQ3,0)),0) | BT3: =IF(AND(OR(Z3="CPF",Z3="CPH"),AY3="SS",BF3="IF"),2%*AT3*AC3,0) | BU3: {=IF(AND(OR(Z3="CPF",Z3="CPH"),OR(BF3="IF",BF3="PU")),_xlfn.IFS(AY3="CS",0.2*BL3,AY3="SS",1*BL3,AY3="PD",0.25*BL3,AY3="PG",0.5*BL3),0)} | BV3: =_xlfn.IFNA(IF(AND(OR(Z3="CPH",Z3="CPF"),OR(BF3="IF",BF3="PU"),BL3<>""),(SUM(BS3:BU3)),0),0) | BW3: =IF(AND(Z3="RBC",BF3="IF"),7%*AT3*AD3,IF(AND(Z3="RBC",BF3="PU"),7%*AT3*AD3*BJ3,0)) | BX3: =IF(AND(Z3="RBC",BF3="IF"),VLOOKUP(AC3,'Rate Table'!$A$9:$G$13,HLOOKUP(DATEDIF('MAINCPF CPH DEP SEP END RBC CSR'!AF3,'MAINCPF CPH DEP SEP END RBC CSR'!AH3, "Y"),'Rate Table'!$B$9:$G$10,2,FALSE),FALSE)*'MAINCPF CPH DEP SEP END RBC CSR'!BL3,0) | BY3: =IF($Z3="RBC",VLOOKUP(A3,'RBC_BONUS CALC'!A:AL,38,FALSE),0) | BZ3: =IF(AND(Z3="RBC",OR(BF3="IF",BF3="PU"),BL3<>""),BL3,0) | CA3: =IF($Z3="DEP",VLOOKUP(A3,'DEP_BONUS CALC'!A:AK,37,0),0) | CB3: =IF(AND(Z3="DEP",OR(BF3="IF",BF3="PU"),BL3<>""),BL3,0) | CC3: =IF(Z3="SEP",IF(BG3=AC3,"Rev. Bonus Due",IF(AD3=BG3,"Sum Assured Due","NA")),"NA") | CD3: {=IF(Z3="SEP",_xlfn.IFS(CC3="Rev. Bonus Due",VLOOKUP(A3,'SEP_BONUS CALC'!A:AL,38,0),CC3="Sum Assured Due",BL3,CC3="NA",0),)} | CE3: =IF($Z3="CSR",VLOOKUP(A3,'CSR_BONUS CALC'!A:AK,37,FALSE),0) | CF3: =IF(Z3<>"CSR","0%",VLOOKUP(AT3,'Rate Table'!$A$2:$F$6,HLOOKUP('MAINCPF CPH DEP SEP END RBC CSR'!AC3,'Rate Table'!$B$2:$F$3,2,FALSE),TRUE))*BL3 | CG3: =IF(AND(Z3="CSR",OR(BF3="IF",BF3="PU"),BL3<>""),CF3+BL3,0) | CH3: {=IF(AND(Z3="CSR",B3="IF"),_xlfn.IFS(AC3=10,AT3*25%,AC3=13,AT3*45%,AC3=16,AT3*70%,AC3=19,AT3*100%,AC3=22,AT3*135%),0)} | CI3: =IF(AND(Z3="CSR",BF3="IF"),IF(((BK3*AD3*100.1%)-CH3)>(CE3+CF3+CG3),((BK3*AD3*100.1%)-CH3)-(CE3+CF3+CG3),0),0) | CJ3: =IF($Z3="END",VLOOKUP(A3,'END_BONUS CALC'!A:AK,37,0),0) | CK3: =IF(AND(Z3="END",BF3="IF"),IF(((BK3*AD3*100.1%)>(CJ3+CL3)),((BK3*AD3*100.1%)-(CJ3+CL3)),0),0) | CL3: =IF(AND(Z3="END",OR(BF3="IF",BF3="PU"),BL3<>""),BL3,0) | CM3: =IF(AND(Z3="END",BF3="IF"),MAX(CJ3+CK3+CL3,-C3*100.1%),IF(AND(Z3="END",BF3="PU"),SUM(CJ3+CK3+CL3)-Q3-SUM(M3:O3),0)) | CO3: =BN3 | CP3: =BS3+BW3 | CQ3: =BT3 | CR3: =IF(AND(Z3="SEP",BL3="Sum Assured Due"),0,BY3+CA3+CD3+CE3+CJ3) | CS3: 0 | CT3: =BX3 | CU3: =IF(AND(Z3="SEP",CC3="Rev. Bonus Due"),0,BU3+BZ3+CB3+CD3+CG3+CL3) | CV3: =CI3+CK3 | CW3: =SUM(CP3:CV3)-Q3-SUM(M3+CO3) | CX3: =SUM(BS3:CN3)-Q3-SUM(M3:O3)
A4: test1010739 | B4: PU | C4: -18364 | E4: -8811.21 | F4: -1836.67 | Q4: -44.25 | S4: 1836.67 | U4: IND | V4: 01APR2005:00:00:00 | W4: 38443 | X4: 4491 | Y4: 119047.6 | Z4: DEP | AA4: TRADITIONAL | AB4: Endowment Plan (Regular) | AC4: 21 | AD4: 21 | AE4: 1 | AF4: 38443 | AG4: 39904 | AH4: 46113 | AI4: 46113 | AJ4: 30502 | AM4: 4591 | AO4: 4591 | AP4: 4591 | AQ4: 0 | AR4: DEP1 | AS4: Endowment Plan (Regular) | AT4: 100000 | AU4: NO | AW4: 19047.6 | BA4: 43 | BB4: 4491 | BC4: 0 | BF4: =B4 | BG4: =DATEDIF(AF4,AH4,"Y") | BH4: =AD4*AE4 | BI4: =ROUND((AG4-AF4)/365*AE4,0) | BJ4: =BI4/BH4 | BK4: {=IF(Z4="CSR",_xlfn.IFS(AE4=1,BB4,AE4=2,BB4/0.52,AE4=4,BB4/0.265,AE4=12,BB4/0.0834),IF(Z4="END",_xlfn.IFS(AE4=1,BB4,AE4=2,BB4/0.51,AE4=4,BB4/0.26,AE4=12,BB4/0.0834),0))} | BL4: =IF(BF4="IF",AT4,IF(BF4="PU",AT4*BI4/BH4,IF(BF4="PM",AT4*BI4/BH4,""))) | BM4: =IF(AH4 <= $BM$1,0,(M4+ N4)*((1 + $BN$1)^((AH4-$BM$1)/365)-1)) | BN4: =N4+BM4 | BO4: =ROUNDDOWN(DATEDIF(AF4,AG4,"Y"),0) | BP4: =IF(B4<>"DH","NA",IF(AND(BO4<3,AG4+IF(AE4<>12,30,15)<AK4),"Lapsed Death",IF(AG4+IF(AE4<>12,30,15)>=AK4,"Inforce Death","Paidup Death"))) | BQ4: =ROUND((AG4-AF4)/365,0) | BR4: =IF(OR(Z4="CPF",Z4="CPH"),VLOOKUP(AY4,'Rate Table'!$B$16:$G$21,2,FALSE),0) | BS4: =IF(OR(Z4="CPF", Z4="CPH"),IF(BF4="IF",2%*AT4*AC4,IF(BF4="PU",2%*AT4*BQ4,0)),0) | BT4: =IF(AND(OR(Z4="CPF",Z4="CPH"),AY4="SS",BF4="IF"),2%*AT4*AC4,0) | BU4: {=IF(AND(OR(Z4="CPF",Z4="CPH"),OR(BF4="IF",BF4="PU")),_xlfn.IFS(AY4="CS",0.2*BL4,AY4="SS",1*BL4,AY4="PD",0.25*BL4,AY4="PG",0.5*BL4),0)} | BV4: =_xlfn.IFNA(IF(AND(OR(Z4="CPH",Z4="CPF"),OR(BF4="IF",BF4="PU"),BL4<>""),(SUM(BS4:BU4)),0),0) | BW4: =IF(AND(Z4="RBC",BF4="IF"),7%*AT4*AD4,IF(AND(Z4="RBC",BF4="PU"),7%*AT4*AD4*BJ4,0)) | BX4: =IF(AND(Z4="RBC",BF4="IF"),VLOOKUP(AC4,'Rate Table'!$A$9:$G$13,HLOOKUP(DATEDIF('MAINCPF CPH DEP SEP END RBC CSR'!AF4,'MAINCPF CPH DEP SEP END RBC CSR'!AH4, "Y"),'Rate Table'!$B$9:$G$10,2,FALSE),FALSE)*'MAINCPF CPH DEP SEP END RBC CSR'!BL4,0) | BY4: =IF($Z4="RBC",VLOOKUP(A4,'RBC_BONUS CALC'!A:AL,38,FALSE),0) | BZ4: =IF(AND(Z4="RBC",OR(BF4="IF",BF4="PU"),BL4<>""),BL4,0) | CA4: =IF($Z4="DEP",VLOOKUP(A4,'DEP_BONUS CALC'!A:AK,37,0),0) | CB4: =IF(AND(Z4="DEP",OR(BF4="IF",BF4="PU"),BL4<>""),BL4,0) | CC4: =IF(Z4="SEP",IF(BG4=AC4,"Rev. Bonus Due",IF(AD4=BG4,"Sum Assured Due","NA")),"NA") | CD4: {=IF(Z4="SEP",_xlfn.IFS(CC4="Rev. Bonus Due",VLOOKUP(A4,'SEP_BONUS CALC'!A:AL,38,0),CC4="Sum Assured Due",BL4,CC4="NA",0),)} | CE4: =IF($Z4="CSR",VLOOKUP(A4,'CSR_BONUS CALC'!A:AK,37,FALSE),0) | CF4: =IF(Z4<>"CSR","0%",VLOOKUP(AT4,'Rate Table'!$A$2:$F$6,HLOOKUP('MAINCPF CPH DEP SEP END RBC CSR'!AC4,'Rate Table'!$B$2:$F$3,2,FALSE),TRUE))*BL4 | CG4: =IF(AND(Z4="CSR",OR(BF4="IF",BF4="PU"),BL4<>""),CF4+BL4,0) | CH4: {=IF(AND(Z4="CSR",B4="IF"),_xlfn.IFS(AC4=10,AT4*25%,AC4=13,AT4*45%,AC4=16,AT4*70%,AC4=19,AT4*100%,AC4=22,AT4*135%),0)} | CI4: =IF(AND(Z4="CSR",BF4="IF"),IF(((BK4*AD4*100.1%)-CH4)>(CE4+CF4+CG4),((BK4*AD4*100.1%)-CH4)-(CE4+CF4+CG4),0),0) | CJ4: =IF($Z4="END",VLOOKUP(A4,'END_BONUS CALC'!A:AK,37,0),0) | CK4: =IF(AND(Z4="END",BF4="IF"),IF(((BK4*AD4*100.1%)>(CJ4+CL4)),((BK4*AD4*100.1%)-(CJ4+CL4)),0),0) | CL4: =IF(AND(Z4="END",OR(BF4="IF",BF4="PU"),BL4<>""),BL4,0) | CM4: =IF(AND(Z4="END",BF4="IF"),MAX(CJ4+CK4+CL4,-C4*100.1%),IF(AND(Z4="END",BF4="PU"),SUM(CJ4+CK4+CL4)-Q4-SUM(M4:O4),0)) | CO4: =BN4 | CP4: =BS4+BW4 | CQ4: =BT4 | CR4: =IF(AND(Z4="SEP",BL4="Sum Assured Due"),0,BY4+CA4+CD4+CE4+CJ4) | CS4: 0 | CT4: =BX4 | CU4: =IF(AND(Z4="SEP",CC4="Rev. Bonus Due"),0,BU4+BZ4+CB4+CD4+CG4+CL4) | CV4: =CI4+CK4 | CW4: =SUM(CP4:CV4)-Q4-SUM(M4+CO4) | CX4: =SUM(BS4:CN4)-Q4-SUM(M4:O4)
A5: test1018255 | B5: PM | C5: -179370 | D5: 155000 | E5: -128333.8 | F5: -1274.72 | Q5: 0 | R5: 0 | S5: 1274.72 | U5: IND | V5: 05APR2006:00:00:00 | W5: 38812 | X5: 5901 | Y5: 155000 | Z5: SEP | AA5: TRADITIONAL | AB5: Special Endowment Plan | AC5: 20 | AD5: 15 | AE5: 2 | AF5: 38812 | AG5: 44291 | AH5: 46117 | AI5: 44291 | AJ5: 26990 | AM5: 0 | AO5: 0 | AP5: 0 | AQ5: 0 | AR5: 37135 | AS5: Special Endowment Plan | AT5: 155000 | AU5: NO | AW5: 155000 | BA5: 53 | BB5: 5901 | BC5: 0 | BF5: =B5 | BG5: =DATEDIF(AF5,AH5,"Y") | BH5: =AD5*AE5 | BI5: =ROUND((AG5-AF5)/365*AE5,0) | BJ5: =BI5/BH5 | BK5: {=IF(Z5="CSR",_xlfn.IFS(AE5=1,BB5,AE5=2,BB5/0.52,AE5=4,BB5/0.265,AE5=12,BB5/0.0834),IF(Z5="END",_xlfn.IFS(AE5=1,BB5,AE5=2,BB5/0.51,AE5=4,BB5/0.26,AE5=12,BB5/0.0834),0))} | BL5: =IF(BF5="IF",AT5,IF(BF5="PU",AT5*BI5/BH5,IF(BF5="PM",AT5*BI5/BH5,""))) | BM5: =IF(AH5 <= $BM$1,0,(M5+ N5)*((1 + $BN$1)^((AH5-$BM$1)/365)-1)) | BN5: =N5+BM5 | BO5: =ROUNDDOWN(DATEDIF(AF5,AG5,"Y"),0) | BP5: =IF(B5<>"DH","NA",IF(AND(BO5<3,AG5+IF(AE5<>12,30,15)<AK5),"Lapsed Death",IF(AG5+IF(AE5<>12,30,15)>=AK5,"Inforce Death","Paidup Death"))) | BQ5: =ROUND((AG5-AF5)/365,0) | BR5: =IF(OR(Z5="CPF",Z5="CPH"),VLOOKUP(AY5,'Rate Table'!$B$16:$G$21,2,FALSE),0) | BS5: =IF(OR(Z5="CPF", Z5="CPH"),IF(BF5="IF",2%*AT5*AC5,IF(BF5="PU",2%*AT5*BQ5,0)),0) | BT5: =IF(AND(OR(Z5="CPF",Z5="CPH"),AY5="SS",BF5="IF"),2%*AT5*AC5,0) | BU5: {=IF(AND(OR(Z5="CPF",Z5="CPH"),OR(BF5="IF",BF5="PU")),_xlfn.IFS(AY5="CS",0.2*BL5,AY5="SS",1*BL5,AY5="PD",0.25*BL5,AY5="PG",0.5*BL5),0)} | BV5: =_xlfn.IFNA(IF(AND(OR(Z5="CPH",Z5="CPF"),OR(BF5="IF",BF5="PU"),BL5<>""),(SUM(BS5:BU5)),0),0) | BW5: =IF(AND(Z5="RBC",BF5="IF"),7%*AT5*AD5,IF(AND(Z5="RBC",BF5="PU"),7%*AT5*AD5*BJ5,0)) | BX5: =IF(AND(Z5="RBC",BF5="IF"),VLOOKUP(AC5,'Rate Table'!$A$9:$G$13,HLOOKUP(DATEDIF('MAINCPF CPH DEP SEP END RBC CSR'!AF5,'MAINCPF CPH DEP SEP END RBC CSR'!AH5, "Y"),'Rate Table'!$B$9:$G$10,2,FALSE),FALSE)*'MAINCPF CPH DEP SEP END RBC CSR'!BL5,0) | BY5: =IF($Z5="RBC",VLOOKUP(A5,'RBC_BONUS CALC'!A:AL,38,FALSE),0) | BZ5: =IF(AND(Z5="RBC",OR(BF5="IF",BF5="PU"),BL5<>""),BL5,0) | CA5: =IF($Z5="DEP",VLOOKUP(A5,'DEP_BONUS CALC'!A:AK,37,0),0) | CB5: =IF(AND(Z5="DEP",OR(BF5="IF",BF5="PU"),BL5<>""),BL5,0) | CC5: =IF(Z5="SEP",IF(BG5=AC5,"Rev. Bonus Due",IF(AD5=BG5,"Sum Assured Due","NA")),"NA") | CD5: {=IF(Z5="SEP",_xlfn.IFS(CC5="Rev. Bonus Due",VLOOKUP(A5,'SEP_BONUS CALC'!A:AL,38,0),CC5="Sum Assured Due",BL5,CC5="NA",0),)} | CE5: =IF($Z5="CSR",VLOOKUP(A5,'CSR_BONUS CALC'!A:AK,37,FALSE),0) | CF5: =IF(Z5<>"CSR","0%",VLOOKUP(AT5,'Rate Table'!$A$2:$F$6,HLOOKUP('MAINCPF CPH DEP SEP END RBC CSR'!AC5,'Rate Table'!$B$2:$F$3,2,FALSE),TRUE))*BL5 | CG5: =IF(AND(Z5="CSR",OR(BF5="IF",BF5="PU"),BL5<>""),CF5+BL5,0) | CH5: {=IF(AND(Z5="CSR",B5="IF"),_xlfn.IFS(AC5=10,AT5*25%,AC5=13,AT5*45%,AC5=16,AT5*70%,AC5=19,AT5*100%,AC5=22,AT5*135%),0)} | CI5: =IF(AND(Z5="CSR",BF5="IF"),IF(((BK5*AD5*100.1%)-CH5)>(CE5+CF5+CG5),((BK5*AD5*100.1%)-CH5)-(CE5+CF5+CG5),0),0) | CJ5: =IF($Z5="END",VLOOKUP(A5,'END_BONUS CALC'!A:AK,37,0),0) | CK5: =IF(AND(Z5="END",BF5="IF"),IF(((BK5*AD5*100.1%)>(CJ5+CL5)),((BK5*AD5*100.1%)-(CJ5+CL5)),0),0) | CL5: =IF(AND(Z5="END",OR(BF5="IF",BF5="PU"),BL5<>""),BL5,0) | CM5: =IF(AND(Z5="END",BF5="IF"),MAX(CJ5+CK5+CL5,-C5*100.1%),IF(AND(Z5="END",BF5="PU"),SUM(CJ5+CK5+CL5)-Q5-SUM(M5:O5),0)) | CO5: =BN5 | CP5: =BS5+BW5 | CQ5: =BT5 | CR5: =IF(AND(Z5="SEP",BL5="Sum Assured Due"),0,BY5+CA5+CD5+CE5+CJ5) | CS5: 0 | CT5: =BX5 | CU5: =IF(AND(Z5="SEP",CC5="Rev. Bonus Due"),0,BU5+BZ5+CB5+CD5+CG5+CL5) | CV5: =CI5+CK5 | CW5: =SUM(CP5:CV5)-Q5-SUM(M5+CO5) | CX5: =SUM(BS5:CN5)-Q5-SUM(M5:O5)
A6: test5260454 | B6: IF | C6: -147560 | E6: -26780 | Q6: -0.28 | U6: IND | V6: 11APR2016:00:00:00 | W6: 42471 | X6: 14756 | Y6: 103000 | Z6: CSR | AA6: TRADITIONAL | AB6: Smart Cash Plus Plan (Regular) | AC6: 10 | AD6: 10 | AE6: 1 | AF6: 42471 | AG6: 46123 | AH6: 46123 | AI6: 46123 | AJ6: 25574 | AM6: 0 | AO6: 0 | AP6: 0 | AQ6: 0 | AR6: CSR1 | AS6: SmartCash Plus-R(Opt I 10*AP) | AT6: 103000 | AU6: NO | AW6: 103000 | BA6: 56 | BB6: 14756 | BC6: 0 | BF6: =B6 | BG6: =DATEDIF(AF6,AH6,"Y") | BH6: =AD6*AE6 | BI6: =ROUND((AG6-AF6)/365*AE6,0) | BJ6: =BI6/BH6 | BK6: {=IF(Z6="CSR",_xlfn.IFS(AE6=1,BB6,AE6=2,BB6/0.52,AE6=4,BB6/0.265,AE6=12,BB6/0.0834),IF(Z6="END",_xlfn.IFS(AE6=1,BB6,AE6=2,BB6/0.51,AE6=4,BB6/0.26,AE6=12,BB6/0.0834),0))} | BL6: =IF(BF6="IF",AT6,IF(BF6="PU",AT6*BI6/BH6,IF(BF6="PM",AT6*BI6/BH6,""))) | BM6: =IF(AH6 <= $BM$1,0,(M6+ N6)*((1 + $BN$1)^((AH6-$BM$1)/365)-1)) | BN6: =N6+BM6 | BO6: =ROUNDDOWN(DATEDIF(AF6,AG6,"Y"),0) | BP6: =IF(B6<>"DH","NA",IF(AND(BO6<3,AG6+IF(AE6<>12,30,15)<AK6),"Lapsed Death",IF(AG6+IF(AE6<>12,30,15)>=AK6,"Inforce Death","Paidup Death"))) | BQ6: =ROUND((AG6-AF6)/365,0) | BR6: =IF(OR(Z6="CPF",Z6="CPH"),VLOOKUP(AY6,'Rate Table'!$B$16:$G$21,2,FALSE),0) | BS6: =IF(OR(Z6="CPF", Z6="CPH"),IF(BF6="IF",2%*AT6*AC6,IF(BF6="PU",2%*AT6*BQ6,0)),0) | BT6: =IF(AND(OR(Z6="CPF",Z6="CPH"),AY6="SS",BF6="IF"),2%*AT6*AC6,0) | BU6: {=IF(AND(OR(Z6="CPF",Z6="CPH"),OR(BF6="IF",BF6="PU")),_xlfn.IFS(AY6="CS",0.2*BL6,AY6="SS",1*BL6,AY6="PD",0.25*BL6,AY6="PG",0.5*BL6),0)} | BV6: =_xlfn.IFNA(IF(AND(OR(Z6="CPH",Z6="CPF"),OR(BF6="IF",BF6="PU"),BL6<>""),(SUM(BS6:BU6)),0),0) | BW6: =IF(AND(Z6="RBC",BF6="IF"),7%*AT6*AD6,IF(AND(Z6="RBC",BF6="PU"),7%*AT6*AD6*BJ6,0)) | BX6: =IF(AND(Z6="RBC",BF6="IF"),VLOOKUP(AC6,'Rate Table'!$A$9:$G$13,HLOOKUP(DATEDIF('MAINCPF CPH DEP SEP END RBC CSR'!AF6,'MAINCPF CPH DEP SEP END RBC CSR'!AH6, "Y"),'Rate Table'!$B$9:$G$10,2,FALSE),FALSE)*'MAINCPF CPH DEP SEP END RBC CSR'!BL6,0) | BY6: =IF($Z6="RBC",VLOOKUP(A6,'RBC_BONUS CALC'!A:AL,38,FALSE),0) | BZ6: =IF(AND(Z6="RBC",OR(BF6="IF",BF6="PU"),BL6<>""),BL6,0) | CA6: =IF($Z6="DEP",VLOOKUP(A6,'DEP_BONUS CALC'!A:AK,37,0),0) | CB6: =IF(AND(Z6="DEP",OR(BF6="IF",BF6="PU"),BL6<>""),BL6,0) | CC6: =IF(Z6="SEP",IF(BG6=AC6,"Rev. Bonus Due",IF(AD6=BG6,"Sum Assured Due","NA")),"NA") | CD6: {=IF(Z6="SEP",_xlfn.IFS(CC6="Rev. Bonus Due",VLOOKUP(A6,'SEP_BONUS CALC'!A:AL,38,0),CC6="Sum Assured Due",BL6,CC6="NA",0),)} | CE6: =IF($Z6="CSR",VLOOKUP(A6,'CSR_BONUS CALC'!A:AK,37,FALSE),0) | CF6: =IF(Z6<>"CSR","0%",VLOOKUP(AT6,'Rate Table'!$A$2:$F$6,HLOOKUP('MAINCPF CPH DEP SEP END RBC CSR'!AC6,'Rate Table'!$B$2:$F$3,2,FALSE),TRUE))*BL6 | CG6: =IF(AND(Z6="CSR",OR(BF6="IF",BF6="PU"),BL6<>""),CF6+BL6,0) | CH6: {=IF(AND(Z6="CSR",B6="IF"),_xlfn.IFS(AC6=10,AT6*25%,AC6=13,AT6*45%,AC6=16,AT6*70%,AC6=19,AT6*100%,AC6=22,AT6*135%),0)} | CI6: =IF(AND(Z6="CSR",BF6="IF"),IF(((BK6*AD6*100.1%)-CH6)>(CE6+CF6+CG6),((BK6*AD6*100.1%)-CH6)-(CE6+CF6+CG6),0),0) | CJ6: =IF($Z6="END",VLOOKUP(A6,'END_BONUS CALC'!A:AK,37,0),0) | CK6: =IF(AND(Z6="END",BF6="IF"),IF(((BK6*AD6*100.1%)>(CJ6+CL6)),((BK6*AD6*100.1%)-(CJ6+CL6)),0),0) | CL6: =IF(AND(Z6="END",OR(BF6="IF",BF6="PU"),BL6<>""),BL6,0) | CM6: =IF(AND(Z6="END",BF6="IF"),MAX(CJ6+CK6+CL6,-C6*100.1%),IF(AND(Z6="END",BF6="PU"),SUM(CJ6+CK6+CL6)-Q6-SUM(M6:O6),0)) | CO6: =BN6 | CP6: =BS6+BW6 | CQ6: =BT6 | CR6: =IF(AND(Z6="SEP",BL6="Sum Assured Due"),0,BY6+CA6+CD6+CE6+CJ6) | CS6: 0 | CT6: =BX6 | CU6: =IF(AND(Z6="SEP",CC6="Rev. Bonus Due"),0,BU6+BZ6+CB6+CD6+CG6+CL6) | CV6: =CI6+CK6 | CW6: =SUM(CP6:CV6)-Q6-SUM(M6+CO6) | CX6: =SUM(BS6:CN6)-Q6-SUM(M6:O6)
A7: test5260579 | B7: IF | C7: -10176114 | Q7: -31.76 | T7: 95712216 | V7: 11APR2016:00:00:00 | W7: 42471 | X7: 731001 | Y7: 7458020 | Z7: CPF | AA7: TRADITIONAL | AB7: Rlnc edu Pln(100% at dth) | AC7: 10 | AD7: 7 | AE7: 2 | AF7: 42471 | AG7: 45027 | AH7: 46123 | AI7: 45027 | AL7: VM | AM7: 0 | AO7: 0 | AP7: 0 | AQ7: 0 | AR7: CPF3 | AS7: Rlnc edu Pln(100% at dth)10X | AT7: 7458020 | AU7: YES | AW7: 7458020 | AY7: SS | BB7: 731001 | BC7: 0 | BF7: =B7 | BG7: =DATEDIF(AF7,AH7,"Y") | BH7: =AD7*AE7 | BI7: =ROUND((AG7-AF7)/365*AE7,0) | BJ7: =BI7/BH7 | BK7: {=IF(Z7="CSR",_xlfn.IFS(AE7=1,BB7,AE7=2,BB7/0.52,AE7=4,BB7/0.265,AE7=12,BB7/0.0834),IF(Z7="END",_xlfn.IFS(AE7=1,BB7,AE7=2,BB7/0.51,AE7=4,BB7/0.26,AE7=12,BB7/0.0834),0))} | BL7: =IF(BF7="IF",AT7,IF(BF7="PU",AT7*BI7/BH7,IF(BF7="PM",AT7*BI7/BH7,""))) | BM7: =IF(AH7 <= $BM$1,0,(M7+ N7)*((1 + $BN$1)^((AH7-$BM$1)/365)-1)) | BN7: =N7+BM7 | BO7: =ROUNDDOWN(DATEDIF(AF7,AG7,"Y"),0) | BP7: =IF(B7<>"DH","NA",IF(AND(BO7<3,AG7+IF(AE7<>12,30,15)<AK7),"Lapsed Death",IF(AG7+IF(AE7<>12,30,15)>=AK7,"Inforce Death","Paidup Death"))) | BQ7: =ROUND((AG7-AF7)/365,0) | BR7: =IF(OR(Z7="CPF",Z7="CPH"),VLOOKUP(AY7,'Rate Table'!$B$16:$G$21,2,FALSE),0) | BS7: =IF(OR(Z7="CPF", Z7="CPH"),IF(BF7="IF",2%*AT7*AC7,IF(BF7="PU",2%*AT7*BQ7,0)),0) | BT7: =IF(AND(OR(Z7="CPF",Z7="CPH"),AY7="SS",BF7="IF"),2%*AT7*AC7,0) | BU7: {=IF(AND(OR(Z7="CPF",Z7="CPH"),OR(BF7="IF",BF7="PU")),_xlfn.IFS(AY7="CS",0.2*BL7,AY7="SS",1*BL7,AY7="PD",0.25*BL7,AY7="PG",0.5*BL7),0)} | BV7: =_xlfn.IFNA(IF(AND(OR(Z7="CPH",Z7="CPF"),OR(BF7="IF",BF7="PU"),BL7<>""),(SUM(BS7:BU7)),0),0) | BW7: =IF(AND(Z7="RBC",BF7="IF"),7%*AT7*AD7,IF(AND(Z7="RBC",BF7="PU"),7%*AT7*AD7*BJ7,0)) | BX7: =IF(AND(Z7="RBC",BF7="IF"),VLOOKUP(AC7,'Rate Table'!$A$9:$G$13,HLOOKUP(DATEDIF('MAINCPF CPH DEP SEP END RBC CSR'!AF7,'MAINCPF CPH DEP SEP END RBC CSR'!AH7, "Y"),'Rate Table'!$B$9:$G$10,2,FALSE),FALSE)*'MAINCPF CPH DEP SEP END RBC CSR'!BL7,0) | BY7: =IF($Z7="RBC",VLOOKUP(A7,'RBC_BONUS CALC'!A:AL,38,FALSE),0) | BZ7: =IF(AND(Z7="RBC",OR(BF7="IF",BF7="PU"),BL7<>""),BL7,0) | CA7: =IF($Z7="DEP",VLOOKUP(A7,'DEP_BONUS CALC'!A:AK,37,0),0) | CB7: =IF(AND(Z7="DEP",OR(BF7="IF",BF7="PU"),BL7<>""),BL7,0) | CC7: =IF(Z7="SEP",IF(BG7=AC7,"Rev. Bonus Due",IF(AD7=BG7,"Sum Assured Due","NA")),"NA") | CD7: {=IF(Z7="SEP",_xlfn.IFS(CC7="Rev. Bonus Due",VLOOKUP(A7,'SEP_BONUS CALC'!A:AL,38,0),CC7="Sum Assured Due",BL7,CC7="NA",0),)} | CE7: =IF($Z7="CSR",VLOOKUP(A7,'CSR_BONUS CALC'!A:AK,37,FALSE),0) | CF7: =IF(Z7<>"CSR","0%",VLOOKUP(AT7,'Rate Table'!$A$2:$F$6,HLOOKUP('MAINCPF CPH DEP SEP END RBC CSR'!AC7,'Rate Table'!$B$2:$F$3,2,FALSE),TRUE))*BL7 | CG7: =IF(AND(Z7="CSR",OR(BF7="IF",BF7="PU"),BL7<>""),CF7+BL7,0) | CH7: {=IF(AND(Z7="CSR",B7="IF"),_xlfn.IFS(AC7=10,AT7*25%,AC7=13,AT7*45%,AC7=16,AT7*70%,AC7=19,AT7*100%,AC7=22,AT7*135%),0)} | CI7: =IF(AND(Z7="CSR",BF7="IF"),IF(((BK7*AD7*100.1%)-CH7)>(CE7+CF7+CG7),((BK7*AD7*100.1%)-CH7)-(CE7+CF7+CG7),0),0) | CJ7: =IF($Z7="END",VLOOKUP(A7,'END_BONUS CALC'!A:AK,37,0),0) | CK7: =IF(AND(Z7="END",BF7="IF"),IF(((BK7*AD7*100.1%)>(CJ7+CL7)),((BK7*AD7*100.1%)-(CJ7+CL7)),0),0) | CL7: =IF(AND(Z7="END",OR(BF7="IF",BF7="PU"),BL7<>""),BL7,0) | CM7: =IF(AND(Z7="END",BF7="IF"),MAX(CJ7+CK7+CL7,-C7*100.1%),IF(AND(Z7="END",BF7="PU"),SUM(CJ7+CK7+CL7)-Q7-SUM(M7:O7),0)) | CO7: =BN7 | CP7: =BS7+BW7 | CQ7: =BT7 | CR7: =IF(AND(Z7="SEP",BL7="Sum Assured Due"),0,BY7+CA7+CD7+CE7+CJ7) | CS7: 0 | CT7: =BX7 | CU7: =IF(AND(Z7="SEP",CC7="Rev. Bonus Due"),0,BU7+BZ7+CB7+CD7+CG7+CL7) | CV7: =CI7+CK7 | CW7: =SUM(CP7:CV7)-Q7-SUM(M7+CO7) | CX7: =SUM(BS7:CN7)-Q7-SUM(M7:O7)
A8: test5261192 | B8: PU | C8: -44748 | E8: -8000 | Q8: -1.45 | U8: IND | V8: 11APR2016:00:00:00 | W8: 42471 | X8: 14916 | Y8: 30000 | Z8: CSR | AA8: TRADITIONAL | AB8: Smart Cash Plus Plan (Regular) | AC8: 10 | AD8: 10 | AE8: 1 | AF8: 42471 | AG8: 43566 | AH8: 46123 | AI8: 46123 | AJ8: 23197 | AM8: 15251.62 | AO8: 15251.62 | AP8: 14916 | AQ8: 335.62 | AR8: CSR1 | AS8: SmartCash Plus-R(Opt I 10*AP) | AT8: 100000 | AU8: NO | AW8: 30000 | BA8: 63 | BB8: 14916 | BC8: 0 | BF8: =B8 | BG8: =DATEDIF(AF8,AH8,"Y") | BH8: =AD8*AE8 | BI8: =ROUND((AG8-AF8)/365*AE8,0) | BJ8: =BI8/BH8 | BK8: {=IF(Z8="CSR",_xlfn.IFS(AE8=1,BB8,AE8=2,BB8/0.52,AE8=4,BB8/0.265,AE8=12,BB8/0.0834),IF(Z8="END",_xlfn.IFS(AE8=1,BB8,AE8=2,BB8/0.51,AE8=4,BB8/0.26,AE8=12,BB8/0.0834),0))} | BL8: =IF(BF8="IF",AT8,IF(BF8="PU",AT8*BI8/BH8,IF(BF8="PM",AT8*BI8/BH8,""))) | BM8: =IF(AH8 <= $BM$1,0,(M8+ N8)*((1 + $BN$1)^((AH8-$BM$1)/365)-1)) | BN8: =N8+BM8 | BO8: =ROUNDDOWN(DATEDIF(AF8,AG8,"Y"),0) | BP8: =IF(B8<>"DH","NA",IF(AND(BO8<3,AG8+IF(AE8<>12,30,15)<AK8),"Lapsed Death",IF(AG8+IF(AE8<>12,30,15)>=AK8,"Inforce Death","Paidup Death"))) | BQ8: =ROUND((AG8-AF8)/365,0) | BR8: =IF(OR(Z8="CPF",Z8="CPH"),VLOOKUP(AY8,'Rate Table'!$B$16:$G$21,2,FALSE),0) | BS8: =IF(OR(Z8="CPF", Z8="CPH"),IF(BF8="IF",2%*AT8*AC8,IF(BF8="PU",2%*AT8*BQ8,0)),0) | BT8: =IF(AND(OR(Z8="CPF",Z8="CPH"),AY8="SS",BF8="IF"),2%*AT8*AC8,0) | BU8: {=IF(AND(OR(Z8="CPF",Z8="CPH"),OR(BF8="IF",BF8="PU")),_xlfn.IFS(AY8="CS",0.2*BL8,AY8="SS",1*BL8,AY8="PD",0.25*BL8,AY8="PG",0.5*BL8),0)} | BV8: =_xlfn.IFNA(IF(AND(OR(Z8="CPH",Z8="CPF"),OR(BF8="IF",BF8="PU"),BL8<>""),(SUM(BS8:BU8)),0),0) | BW8: =IF(AND(Z8="RBC",BF8="IF"),7%*AT8*AD8,IF(AND(Z8="RBC",BF8="PU"),7%*AT8*AD8*BJ8,0)) | BX8: =IF(AND(Z8="RBC",BF8="IF"),VLOOKUP(AC8,'Rate Table'!$A$9:$G$13,HLOOKUP(DATEDIF('MAINCPF CPH DEP SEP END RBC CSR'!AF8,'MAINCPF CPH DEP SEP END RBC CSR'!AH8, "Y"),'Rate Table'!$B$9:$G$10,2,FALSE),FALSE)*'MAINCPF CPH DEP SEP END RBC CSR'!BL8,0) | BY8: =IF($Z8="RBC",VLOOKUP(A8,'RBC_BONUS CALC'!A:AL,38,FALSE),0) | BZ8: =IF(AND(Z8="RBC",OR(BF8="IF",BF8="PU"),BL8<>""),BL8,0) | CA8: =IF($Z8="DEP",VLOOKUP(A8,'DEP_BONUS CALC'!A:AK,37,0),0) | CB8: =IF(AND(Z8="DEP",OR(BF8="IF",BF8="PU"),BL8<>""),BL8,0) | CC8: =IF(Z8="SEP",IF(BG8=AC8,"Rev. Bonus Due",IF(AD8=BG8,"Sum Assured Due","NA")),"NA") | CD8: {=IF(Z8="SEP",_xlfn.IFS(CC8="Rev. Bonus Due",VLOOKUP(A8,'SEP_BONUS CALC'!A:AL,38,0),CC8="Sum Assured Due",BL8,CC8="NA",0),)} | CE8: =IF($Z8="CSR",VLOOKUP(A8,'CSR_BONUS CALC'!A:AK,37,FALSE),0) | CF8: =IF(Z8<>"CSR","0%",VLOOKUP(AT8,'Rate Table'!$A$2:$F$6,HLOOKUP('MAINCPF CPH DEP SEP END RBC CSR'!AC8,'Rate Table'!$B$2:$F$3,2,FALSE),TRUE))*BL8 | CG8: =IF(AND(Z8="CSR",OR(BF8="IF",BF8="PU"),BL8<>""),CF8+BL8,0) | CH8: {=IF(AND(Z8="CSR",B8="IF"),_xlfn.IFS(AC8=10,AT8*25%,AC8=13,AT8*45%,AC8=16,AT8*70%,AC8=19,AT8*100%,AC8=22,AT8*135%),0)} | CI8: =IF(AND(Z8="CSR",BF8="IF"),IF(((BK8*AD8*100.1%)-CH8)>(CE8+CF8+CG8),((BK8*AD8*100.1%)-CH8)-(CE8+CF8+CG8),0),0) | CJ8: =IF($Z8="END",VLOOKUP(A8,'END_BONUS CALC'!A:AK,37,0),0) | CK8: =IF(AND(Z8="END",BF8="IF"),IF(((BK8*AD8*100.1%)>(CJ8+CL8)),((BK8*AD8*100.1%)-(CJ8+CL8)),0),0) | CL8: =IF(AND(Z8="END",OR(BF8="IF",BF8="PU"),BL8<>""),BL8,0) | CM8: =IF(AND(Z8="END",BF8="IF"),MAX(CJ8+CK8+CL8,-C8*100.1%),IF(AND(Z8="END",BF8="PU"),SUM(CJ8+CK8+CL8)-Q8-SUM(M8:O8),0)) | CO8: =BN8 | CP8: =BS8+BW8 | CQ8: =BT8 | CR8: =IF(AND(Z8="SEP",BL8="Sum Assured Due"),0,BY8+CA8+CD8+CE8+CJ8) | CS8: 0 | CT8: =BX8 | CU8: =IF(AND(Z8="SEP",CC8="Rev. Bonus Due"),0,BU8+BZ8+CB8+CD8+CG8+CL8) | CV8: =CI8+CK8 | CW8: =SUM(CP8:CV8)-Q8-SUM(M8+CO8) | CX8: =SUM(BS8:CN8)-Q8-SUM(M8:O8)
A9: test5261716 | B9: IF | C9: -105190 | E9: -13656.48 | Q9: -0.34 | U9: IND | V9: 11APR2016:00:00:00 | W9: 42471 | X9: 10519 | Y9: 70000 | Z9: END | AA9: TRADITIONAL | AB9: Endowment Plan (Rev) | AC9: 10 | AD9: 10 | AE9: 1 | AF9: 42471 | AG9: 46123 | AH9: 46123 | AI9: 46123 | AJ9: 24476 | AM9: 0 | AO9: 0 | AP9: 0 | AQ9: 0 | AR9: END1 | AS9: Endowment Plan (Rev) | AT9: 70000 | AU9: NO | AW9: 70000 | BA9: 59 | BB9: 10519 | BC9: 0 | BD9: 1 | BF9: =B9 | BG9: =DATEDIF(AF9,AH9,"Y") | BH9: =AD9*AE9 | BI9: =ROUND((AG9-AF9)/365*AE9,0) | BJ9: =BI9/BH9 | BK9: {=IF(Z9="CSR",_xlfn.IFS(AE9=1,BB9,AE9=2,BB9/0.52,AE9=4,BB9/0.265,AE9=12,BB9/0.0834),IF(Z9="END",_xlfn.IFS(AE9=1,BB9,AE9=2,BB9/0.51,AE9=4,BB9/0.26,AE9=12,BB9/0.0834),0))} | BL9: =IF(BF9="IF",AT9,IF(BF9="PU",AT9*BI9/BH9,IF(BF9="PM",AT9*BI9/BH9,""))) | BM9: =IF(AH9 <= $BM$1,0,(M9+ N9)*((1 + $BN$1)^((AH9-$BM$1)/365)-1)) | BN9: =N9+BM9 | BO9: =ROUNDDOWN(DATEDIF(AF9,AG9,"Y"),0) | BP9: =IF(B9<>"DH","NA",IF(AND(BO9<3,AG9+IF(AE9<>12,30,15)<AK9),"Lapsed Death",IF(AG9+IF(AE9<>12,30,15)>=AK9,"Inforce Death","Paidup Death"))) | BQ9: =ROUND((AG9-AF9)/365,0) | BR9: =IF(OR(Z9="CPF",Z9="CPH"),VLOOKUP(AY9,'Rate Table'!$B$16:$G$21,2,FALSE),0) | BS9: =IF(OR(Z9="CPF", Z9="CPH"),IF(BF9="IF",2%*AT9*AC9,IF(BF9="PU",2%*AT9*BQ9,0)),0) | BT9: =IF(AND(OR(Z9="CPF",Z9="CPH"),AY9="SS",BF9="IF"),2%*AT9*AC9,0) | BU9: {=IF(AND(OR(Z9="CPF",Z9="CPH"),OR(BF9="IF",BF9="PU")),_xlfn.IFS(AY9="CS",0.2*BL9,AY9="SS",1*BL9,AY9="PD",0.25*BL9,AY9="PG",0.5*BL9),0)} | BV9: =_xlfn.IFNA(IF(AND(OR(Z9="CPH",Z9="CPF"),OR(BF9="IF",BF9="PU"),BL9<>""),(SUM(BS9:BU9)),0),0) | BW9: =IF(AND(Z9="RBC",BF9="IF"),7%*AT9*AD9,IF(AND(Z9="RBC",BF9="PU"),7%*AT9*AD9*BJ9,0)) | BX9: =IF(AND(Z9="RBC",BF9="IF"),VLOOKUP(AC9,'Rate Table'!$A$9:$G$13,HLOOKUP(DATEDIF('MAINCPF CPH DEP SEP END RBC CSR'!AF9,'MAINCPF CPH DEP SEP END RBC CSR'!AH9, "Y"),'Rate Table'!$B$9:$G$10,2,FALSE),FALSE)*'MAINCPF CPH DEP SEP END RBC CSR'!BL9,0) | BY9: =IF($Z9="RBC",VLOOKUP(A9,'RBC_BONUS CALC'!A:AL,38,FALSE),0) | BZ9: =IF(AND(Z9="RBC",OR(BF9="IF",BF9="PU"),BL9<>""),BL9,0) | CA9: =IF($Z9="DEP",VLOOKUP(A9,'DEP_BONUS CALC'!A:AK,37,0),0) | CB9: =IF(AND(Z9="DEP",OR(BF9="IF",BF9="PU"),BL9<>""),BL9,0) | CC9: =IF(Z9="SEP",IF(BG9=AC9,"Rev. Bonus Due",IF(AD9=BG9,"Sum Assured Due","NA")),"NA") | CD9: {=IF(Z9="SEP",_xlfn.IFS(CC9="Rev. Bonus Due",VLOOKUP(A9,'SEP_BONUS CALC'!A:AL,38,0),CC9="Sum Assured Due",BL9,CC9="NA",0),)} | CE9: =IF($Z9="CSR",VLOOKUP(A9,'CSR_BONUS CALC'!A:AK,37,FALSE),0) | CF9: =IF(Z9<>"CSR","0%",VLOOKUP(AT9,'Rate Table'!$A$2:$F$6,HLOOKUP('MAINCPF CPH DEP SEP END RBC CSR'!AC9,'Rate Table'!$B$2:$F$3,2,FALSE),TRUE))*BL9 | CG9: =IF(AND(Z9="CSR",OR(BF9="IF",BF9="PU"),BL9<>""),CF9+BL9,0) | CH9: {=IF(AND(Z9="CSR",B9="IF"),_xlfn.IFS(AC9=10,AT9*25%,AC9=13,AT9*45%,AC9=16,AT9*70%,AC9=19,AT9*100%,AC9=22,AT9*135%),0)} | CI9: =IF(AND(Z9="CSR",BF9="IF"),IF(((BK9*AD9*100.1%)-CH9)>(CE9+CF9+CG9),((BK9*AD9*100.1%)-CH9)-(CE9+CF9+CG9),0),0) | CJ9: =IF($Z9="END",VLOOKUP(A9,'END_BONUS CALC'!A:AK,37,0),0) | CK9: =IF(AND(Z9="END",BF9="IF"),IF(((BK9*AD9*100.1%)>(CJ9+CL9)),((BK9*AD9*100.1%)-(CJ9+CL9)),0),0) | CL9: =IF(AND(Z9="END",OR(BF9="IF",BF9="PU"),BL9<>""),BL9,0) | CM9: =IF(AND(Z9="END",BF9="IF"),MAX(CJ9+CK9+CL9,-C9*100.1%),IF(AND(Z9="END",BF9="PU"),SUM(CJ9+CK9+CL9)-Q9-SUM(M9:O9),0)) | CO9: =BN9 | CP9: =BS9+BW9 | CQ9: =BT9 | CR9: =IF(AND(Z9="SEP",BL9="Sum Assured Due"),0,BY9+CA9+CD9+CE9+CJ9) | CS9: 0 | CT9: =BX9 | CU9: =IF(AND(Z9="SEP",CC9="Rev. Bonus Due"),0,BU9+BZ9+CB9+CD9+CG9+CL9) | CV9: =CI9+CK9 | CW9: =SUM(CP9:CV9)-Q9-SUM(M9+CO9) | CX9: =SUM(BS9:CN9)-Q9-SUM(M9:O9)
A10: test5262934 | B10: PU | C10: -93048 | E10: -14508.68 | M10: 43285 | N10: 10355.62 | O10: -10355.62 | Q10: -0.49 | T10: 215617 | U10: IND | V10: 11APR2016:00:00:00 | W10: 42471 | X10: 7754 | Y10: 69000 | Z10: END | AA10: TRADITIONAL | AB10: Endowment Plan (Rev) | AC10: 10 | AD10: 10 | AE10: 2 | AF10: 42471 | AG10: 44662 | AH10: 46123 | AI10: 46123 | AJ10: 32320 | AM10: 15856.92 | AO10: 7928.46 | AP10: 7754 | AQ10: 174.46 | AR10: END1 | AS10: Endowment Plan (Rev) | AT10: 115000 | AU10: YES | AW10: 69000 | BA10: 38 | BB10: 7754 | BC10: 0 | BD10: 0.51 | BF10: =B10 | BG10: =DATEDIF(AF10,AH10,"Y") | BH10: =AD10*AE10 | BI10: =ROUND((AG10-AF10)/365*AE10,0) | BJ10: =BI10/BH10 | BK10: {=IF(Z10="CSR",_xlfn.IFS(AE10=1,BB10,AE10=2,BB10/0.52,AE10=4,BB10/0.265,AE10=12,BB10/0.0834),IF(Z10="END",_xlfn.IFS(AE10=1,BB10,AE10=2,BB10/0.51,AE10=4,BB10/0.26,AE10=12,BB10/0.0834),0))} | BL10: =IF(BF10="IF",AT10,IF(BF10="PU",AT10*BI10/BH10,IF(BF10="PM",AT10*BI10/BH10,""))) | BM10: =IF(AH10 <= $BM$1,0,(M10+ N10)*((1 + $BN$1)^((AH10-$BM$1)/365)-1)) | BN10: =N10+BM10 | BO10: =ROUNDDOWN(DATEDIF(AF10,AG10,"Y"),0) | BP10: =IF(B10<>"DH","NA",IF(AND(BO10<3,AG10+IF(AE10<>12,30,15)<AK10),"Lapsed Death",IF(AG10+IF(AE10<>12,30,15)>=AK10,"Inforce Death","Paidup Death"))) | BQ10: =ROUND((AG10-AF10)/365,0) | BR10: =IF(OR(Z10="CPF",Z10="CPH"),VLOOKUP(AY10,'Rate Table'!$B$16:$G$21,2,FALSE),0) | BS10: =IF(OR(Z10="CPF", Z10="CPH"),IF(BF10="IF",2%*AT10*AC10,IF(BF10="PU",2%*AT10*BQ10,0)),0) | BT10: =IF(AND(OR(Z10="CPF",Z10="CPH"),AY10="SS",BF10="IF"),2%*AT10*AC10,0) | BU10: {=IF(AND(OR(Z10="CPF",Z10="CPH"),OR(BF10="IF",BF10="PU")),_xlfn.IFS(AY10="CS",0.2*BL10,AY10="SS",1*BL10,AY10="PD",0.25*BL10,AY10="PG",0.5*BL10),0)} | BV10: =_xlfn.IFNA(IF(AND(OR(Z10="CPH",Z10="CPF"),OR(BF10="IF",BF10="PU"),BL10<>""),(SUM(BS10:BU10)),0),0) | BW10: =IF(AND(Z10="RBC",BF10="IF"),7%*AT10*AD10,IF(AND(Z10="RBC",BF10="PU"),7%*AT10*AD10*BJ10,0)) | BX10: =IF(AND(Z10="RBC",BF10="IF"),VLOOKUP(AC10,'Rate Table'!$A$9:$G$13,HLOOKUP(DATEDIF('MAINCPF CPH DEP SEP END RBC CSR'!AF10,'MAINCPF CPH DEP SEP END RBC CSR'!AH10, "Y"),'Rate Table'!$B$9:$G$10,2,FALSE),FALSE)*'MAINCPF CPH DEP SEP END RBC CSR'!BL10,0) | BY10: =IF($Z10="RBC",VLOOKUP(A10,'RBC_BONUS CALC'!A:AL,38,FALSE),0) | BZ10: =IF(AND(Z10="RBC",OR(BF10="IF",BF10="PU"),BL10<>""),BL10,0) | CA10: =IF($Z10="DEP",VLOOKUP(A10,'DEP_BONUS CALC'!A:AK,37,0),0) | CB10: =IF(AND(Z10="DEP",OR(BF10="IF",BF10="PU"),BL10<>""),BL10,0) | CC10: =IF(Z10="SEP",IF(BG10=AC10,"Rev. Bonus Due",IF(AD10=BG10,"Sum Assured Due","NA")),"NA") | CD10: {=IF(Z10="SEP",_xlfn.IFS(CC10="Rev. Bonus Due",VLOOKUP(A10,'SEP_BONUS CALC'!A:AL,38,0),CC10="Sum Assured Due",BL10,CC10="NA",0),)} | CE10: =IF($Z10="CSR",VLOOKUP(A10,'CSR_BONUS CALC'!A:AK,37,FALSE),0) | CF10: =IF(Z10<>"CSR","0%",VLOOKUP(AT10,'Rate Table'!$A$2:$F$6,HLOOKUP('MAINCPF CPH DEP SEP END RBC CSR'!AC10,'Rate Table'!$B$2:$F$3,2,FALSE),TRUE))*BL10 | CG10: =IF(AND(Z10="CSR",OR(BF10="IF",BF10="PU"),BL10<>""),CF10+BL10,0) | CH10: {=IF(AND(Z10="CSR",B10="IF"),_xlfn.IFS(AC10=10,AT10*25%,AC10=13,AT10*45%,AC10=16,AT10*70%,AC10=19,AT10*100%,AC10=22,AT10*135%),0)} | CI10: =IF(AND(Z10="CSR",BF10="IF"),IF(((BK10*AD10*100.1%)-CH10)>(CE10+CF10+CG10),((BK10*AD10*100.1%)-CH10)-(CE10+CF10+CG10),0),0) | CJ10: =IF($Z10="END",VLOOKUP(A10,'END_BONUS CALC'!A:AK,37,0),0) | CK10: =IF(AND(Z10="END",BF10="IF"),IF(((BK10*AD10*100.1%)>(CJ10+CL10)),((BK10*AD10*100.1%)-(CJ10+CL10)),0),0) | CL10: =IF(AND(Z10="END",OR(BF10="IF",BF10="PU"),BL10<>""),BL10,0) | CM10: =IF(AND(Z10="END",BF10="IF"),MAX(CJ10+CK10+CL10,-C10*100.1%),IF(AND(Z10="END",BF10="PU"),SUM(CJ10+CK10+CL10)-Q10-SUM(M10:O10),0)) | CO10: =BN10 | CP10: =BS10+BW10 | CQ10: =BT10 | CR10: =IF(AND(Z10="SEP",BL10="Sum Assured Due"),0,BY10+CA10+CD10+CE10+CJ10) | CS10: 0 | CT10: =BX10 | CU10: =IF(AND(Z10="SEP",CC10="Rev. Bonus Due"),0,BU10+BZ10+CB10+CD10+CG10+CL10) | CV10: =CI10+CK10 | CW10: =SUM(CP10:CV10)-Q10-SUM(M10+CO10) | CX10: =SUM(BS10:CN10)-Q10-SUM(M10:O10)
A11: test5263254 | B11: IF | C11: -240240 | E11: -77169.33 | Q11: 0 | U11: IND | V11: 14APR2016:00:00:00 | W11: 42474 | X11: 4004 | Y11: 139734 | Z11: RBC | AA11: TRADITIONAL | AB11: Reliance Blue Chip Plan | AC11: 10 | AD11: 5 | AE11: 12 | AF11: 42474 | AG11: 44300 | AH11: 46126 | AI11: 44300 | AJ11: 25848 | AL11: VM | AM11: 0 | AO11: 0 | AP11: 0 | AQ11: 0 | AR11: RBC1 | AS11: Reliance Blue chip 10X SA. | AT11: 139734 | AU11: NO | AW11: 139734 | BA11: 56 | BB11: 4004 | BC11: 0 | BF11: =B11 | BG11: =DATEDIF(AF11,AH11,"Y") | BH11: =AD11*AE11 | BI11: =ROUND((AG11-AF11)/365*AE11,0) | BJ11: =BI11/BH11 | BK11: {=IF(Z11="CSR",_xlfn.IFS(AE11=1,BB11,AE11=2,BB11/0.52,AE11=4,BB11/0.265,AE11=12,BB11/0.0834),IF(Z11="END",_xlfn.IFS(AE11=1,BB11,AE11=2,BB11/0.51,AE11=4,BB11/0.26,AE11=12,BB11/0.0834),0))} | BL11: =IF(BF11="IF",AT11,IF(BF11="PU",AT11*BI11/BH11,IF(BF11="PM",AT11*BI11/BH11,""))) | BM11: =IF(AH11 <= $BM$1,0,(M11+ N11)*((1 + $BN$1)^((AH11-$BM$1)/365)-1)) | BN11: =N11+BM11 | BO11: =ROUNDDOWN(DATEDIF(AF11,AG11,"Y"),0) | BP11: =IF(B11<>"DH","NA",IF(AND(BO11<3,AG11+IF(AE11<>12,30,15)<AK11),"Lapsed Death",IF(AG11+IF(AE11<>12,30,15)>=AK11,"Inforce Death","Paidup Death"))) | BQ11: =ROUND((AG11-AF11)/365,0) | BR11: =IF(OR(Z11="CPF",Z11="CPH"),VLOOKUP(AY11,'Rate Table'!$B$16:$G$21,2,FALSE),0) | BS11: =IF(OR(Z11="CPF", Z11="CPH"),IF(BF11="IF",2%*AT11*AC11,IF(BF11="PU",2%*AT11*BQ11,0)),0) | BT11: =IF(AND(OR(Z11="CPF",Z11="CPH"),AY11="SS",BF11="IF"),2%*AT11*AC11,0) | BU11: {=IF(AND(OR(Z11="CPF",Z11="CPH"),OR(BF11="IF",BF11="PU")),_xlfn.IFS(AY11="CS",0.2*BL11,AY11="SS",1*BL11,AY11="PD",0.25*BL11,AY11="PG",0.5*BL11),0)} | BV11: =_xlfn.IFNA(IF(AND(OR(Z11="CPH",Z11="CPF"),OR(BF11="IF",BF11="PU"),BL11<>""),(SUM(BS11:BU11)),0),0) | BW11: =IF(AND(Z11="RBC",BF11="IF"),7%*AT11*AD11,IF(AND(Z11="RBC",BF11="PU"),7%*AT11*AD11*BJ11,0)) | BX11: =IF(AND(Z11="RBC",BF11="IF"),VLOOKUP(AC11,'Rate Table'!$A$9:$G$13,HLOOKUP(DATEDIF('MAINCPF CPH DEP SEP END RBC CSR'!AF11,'MAINCPF CPH DEP SEP END RBC CSR'!AH11, "Y"),'Rate Table'!$B$9:$G$10,2,FALSE),FALSE)*'MAINCPF CPH DEP SEP END RBC CSR'!BL11,0) | BY11: =IF($Z11="RBC",VLOOKUP(A11,'RBC_BONUS CALC'!A:AL,38,FALSE),0) | BZ11: =IF(AND(Z11="RBC",OR(BF11="IF",BF11="PU"),BL11<>""),BL11,0) | CA11: =IF($Z11="DEP",VLOOKUP(A11,'DEP_BONUS CALC'!A:AK,37,0),0) | CB11: =IF(AND(Z11="DEP",OR(BF11="IF",BF11="PU"),BL11<>""),BL11,0) | CC11: =IF(Z11="SEP",IF(BG11=AC11,"Rev. Bonus Due",IF(AD11=BG11,"Sum Assured Due","NA")),"NA") | CD11: {=IF(Z11="SEP",_xlfn.IFS(CC11="Rev. Bonus Due",VLOOKUP(A11,'SEP_BONUS CALC'!A:AL,38,0),CC11="Sum Assured Due",BL11,CC11="NA",0),)} | CE11: =IF($Z11="CSR",VLOOKUP(A11,'CSR_BONUS CALC'!A:AK,37,FALSE),0) | CF11: =IF(Z11<>"CSR","0%",VLOOKUP(AT11,'Rate Table'!$A$2:$F$6,HLOOKUP('MAINCPF CPH DEP SEP END RBC CSR'!AC11,'Rate Table'!$B$2:$F$3,2,FALSE),TRUE))*BL11 | CG11: =IF(AND(Z11="CSR",OR(BF11="IF",BF11="PU"),BL11<>""),CF11+BL11,0) | CH11: {=IF(AND(Z11="CSR",B11="IF"),_xlfn.IFS(AC11=10,AT11*25%,AC11=13,AT11*45%,AC11=16,AT11*70%,AC11=19,AT11*100%,AC11=22,AT11*135%),0)} | CI11: =IF(AND(Z11="CSR",BF11="IF"),IF(((BK11*AD11*100.1%)-CH11)>(CE11+CF11+CG11),((BK11*AD11*100.1%)-CH11)-(CE11+CF11+CG11),0),0) | CJ11: =IF($Z11="END",VLOOKUP(A11,'END_BONUS CALC'!A:AK,37,0),0) | CK11: =IF(AND(Z11="END",BF11="IF"),IF(((BK11*AD11*100.1%)>(CJ11+CL11)),((BK11*AD11*100.1%)-(CJ11+CL11)),0),0) | CL11: =IF(AND(Z11="END",OR(BF11="IF",BF11="PU"),BL11<>""),BL11,0) | CM11: =IF(AND(Z11="END",BF11="IF"),MAX(CJ11+CK11+CL11,-C11*100.1%),IF(AND(Z11="END",BF11="PU"),SUM(CJ11+CK11+CL11)-Q11-SUM(M11:O11),0)) | CO11: =BN11 | CP11: =BS11+BW11 | CQ11: =BT11 | CR11: =IF(AND(Z11="SEP",BL11="Sum Assured Due"),0,BY11+CA11+CD11+CE11+CJ11) | CS11: 0 | CT11: =BX11 | CU11: =IF(AND(Z11="SEP",CC11="Rev. Bonus Due"),0,BU11+BZ11+CB11+CD11+CG11+CL11) | CV11: =CI11+CK11 | CW11: =SUM(CP11:CV11)-Q11-SUM(M11+CO11) | CX11: =SUM(BS11:CN11)-Q11-SUM(M11:O11)
A12: test5263328 | B12: PU | C12: -1930040 | E12: -338124.4 | Q12: -0.04 | U12: IND | V12: 15APR2016:00:00:00 | W12: 42475 | X12: 482510 | Y12: 1229543.2 | Z12: RBC | AA12: TRADITIONAL | AB12: Reliance Blue Chip Plan | AC12: 10 | AD12: 5 | AE12: 1 | AF12: 42475 | AG12: 43936 | AH12: 46127 | AI12: 44301 | AJ12: 30926 | AL12: VM | AM12: 493969.62 | AO12: 493969.62 | AP12: 482510 | AQ12: 11459.62 | AR12: RBC1 | AS12: Reliance Blue chip 10X SA. | AT12: 1536929 | AU12: NO | AW12: 1229543.2 | BA12: 42 | BB12: 482510 | BC12: 0 | BF12: =B12 | BG12: =DATEDIF(AF12,AH12,"Y") | BH12: =AD12*AE12 | BI12: =ROUND((AG12-AF12)/365*AE12,0) | BJ12: =BI12/BH12 | BK12: {=IF(Z12="CSR",_xlfn.IFS(AE12=1,BB12,AE12=2,BB12/0.52,AE12=4,BB12/0.265,AE12=12,BB12/0.0834),IF(Z12="END",_xlfn.IFS(AE12=1,BB12,AE12=2,BB12/0.51,AE12=4,BB12/0.26,AE12=12,BB12/0.0834),0))} | BL12: =IF(BF12="IF",AT12,IF(BF12="PU",AT12*BI12/BH12,IF(BF12="PM",AT12*BI12/BH12,""))) | BM12: =IF(AH12 <= $BM$1,0,(M12+ N12)*((1 + $BN$1)^((AH12-$BM$1)/365)-1)) | BN12: =N12+BM12 | BO12: =ROUNDDOWN(DATEDIF(AF12,AG12,"Y"),0) | BP12: =IF(B12<>"DH","NA",IF(AND(BO12<3,AG12+IF(AE12<>12,30,15)<AK12),"Lapsed Death",IF(AG12+IF(AE12<>12,30,15)>=AK12,"Inforce Death","Paidup Death"))) | BQ12: =ROUND((AG12-AF12)/365,0) | BR12: =IF(OR(Z12="CPF",Z12="CPH"),VLOOKUP(AY12,'Rate Table'!$B$16:$G$21,2,FALSE),0) | BS12: =IF(OR(Z12="CPF", Z12="CPH"),IF(BF12="IF",2%*AT12*AC12,IF(BF12="PU",2%*AT12*BQ12,0)),0) | BT12: =IF(AND(OR(Z12="CPF",Z12="CPH"),AY12="SS",BF12="IF"),2%*AT12*AC12,0) | BU12: {=IF(AND(OR(Z12="CPF",Z12="CPH"),OR(BF12="IF",BF12="PU")),_xlfn.IFS(AY12="CS",0.2*BL12,AY12="SS",1*BL12,AY12="PD",0.25*BL12,AY12="PG",0.5*BL12),0)} | BV12: =_xlfn.IFNA(IF(AND(OR(Z12="CPH",Z12="CPF"),OR(BF12="IF",BF12="PU"),BL12<>""),(SUM(BS12:BU12)),0),0) | BW12: =IF(AND(Z12="RBC",BF12="IF"),7%*AT12*AD12,IF(AND(Z12="RBC",BF12="PU"),7%*AT12*AD12*BJ12,0)) | BX12: =IF(AND(Z12="RBC",BF12="IF"),VLOOKUP(AC12,'Rate Table'!$A$9:$G$13,HLOOKUP(DATEDIF('MAINCPF CPH DEP SEP END RBC CSR'!AF12,'MAINCPF CPH DEP SEP END RBC CSR'!AH12, "Y"),'Rate Table'!$B$9:$G$10,2,FALSE),FALSE)*'MAINCPF CPH DEP SEP END RBC CSR'!BL12,0) | BY12: =IF($Z12="RBC",VLOOKUP(A12,'RBC_BONUS CALC'!A:AL,38,FALSE),0) | BZ12: =IF(AND(Z12="RBC",OR(BF12="IF",BF12="PU"),BL12<>""),BL12,0) | CA12: =IF($Z12="DEP",VLOOKUP(A12,'DEP_BONUS CALC'!A:AK,37,0),0) | CB12: =IF(AND(Z12="DEP",OR(BF12="IF",BF12="PU"),BL12<>""),BL12,0) | CC12: =IF(Z12="SEP",IF(BG12=AC12,"Rev. Bonus Due",IF(AD12=BG12,"Sum Assured Due","NA")),"NA") | CD12: {=IF(Z12="SEP",_xlfn.IFS(CC12="Rev. Bonus Due",VLOOKUP(A12,'SEP_BONUS CALC'!A:AL,38,0),CC12="Sum Assured Due",BL12,CC12="NA",0),)} | CE12: =IF($Z12="CSR",VLOOKUP(A12,'CSR_BONUS CALC'!A:AK,37,FALSE),0) | CF12: =IF(Z12<>"CSR","0%",VLOOKUP(AT12,'Rate Table'!$A$2:$F$6,HLOOKUP('MAINCPF CPH DEP SEP END RBC CSR'!AC12,'Rate Table'!$B$2:$F$3,2,FALSE),TRUE))*BL12 | CG12: =IF(AND(Z12="CSR",OR(BF12="IF",BF12="PU"),BL12<>""),CF12+BL12,0) | CH12: {=IF(AND(Z12="CSR",B12="IF"),_xlfn.IFS(AC12=10,AT12*25%,AC12=13,AT12*45%,AC12=16,AT12*70%,AC12=19,AT12*100%,AC12=22,AT12*135%),0)} | CI12: =IF(AND(Z12="CSR",BF12="IF"),IF(((BK12*AD12*100.1%)-CH12)>(CE12+CF12+CG12),((BK12*AD12*100.1%)-CH12)-(CE12+CF12+CG12),0),0) | CJ12: =IF($Z12="END",VLOOKUP(A12,'END_BONUS CALC'!A:AK,37,0),0) | CK12: =IF(AND(Z12="END",BF12="IF"),IF(((BK12*AD12*100.1%)>(CJ12+CL12)),((BK12*AD12*100.1%)-(CJ12+CL12)),0),0) | CL12: =IF(AND(Z12="END",OR(BF12="IF",BF12="PU"),BL12<>""),BL12,0) | CM12: =IF(AND(Z12="END",BF12="IF"),MAX(CJ12+CK12+CL12,-C12*100.1%),IF(AND(Z12="END",BF12="PU"),SUM(CJ12+CK12+CL12)-Q12-SUM(M12:O12),0)) | CO12: =BN12 | CP12: =BS12+BW12 | CQ12: =BT12 | CR12: =IF(AND(Z12="SEP",BL12="Sum Assured Due"),0,BY12+CA12+CD12+CE12+CJ12) | CS12: 0 | CT12: =BX12 | CU12: =IF(AND(Z12="SEP",CC12="Rev. Bonus Due"),0,BU12+BZ12+CB12+CD12+CG12+CL12) | CV12: =CI12+CK12 | CW12: =SUM(CP12:CV12)-Q12-SUM(M12+CO12) | CX12: =SUM(BS12:CN12)-Q12-SUM(M12:O12)
BK4154: 16045
BS1047809: =IF(Z1047809="SEP",IF(BG1047809=AC1047809,"Rev. Bonus Due",IF(AD1047809=BG1047809,"Sum Assured Due","NA")),"NA") | CN1047809: =IF(Z1047809="SEP",VLOOKUP(A1047809,'SEP_BONUS CALC'!#REF!,37,0),"0")

Sheet DEP_BONUS CALC
A1: Current year | B1: 2026 | D1: 1 | I1: Not to be deleted | K1: 2001 | L1: 2002 | M1: 2003 | N1: 2004 | O1: 2005 | P1: 2006 | Q1: 2007 | R1: 2008 | S1: 2009 | T1: 2010 | U1: 2011 | V1: 2012 | W1: 2013 | X1: 2014 | Y1: 2015 | Z1: 2016 | AA1: 2017 | AB1: 2018 | AC1: 2019 | AD1: 2020 | AE1: 2021 | AF1: 2022 | AG1: 2023 | AH1: 2024 | AI1: 2025 | AJ1: 2026
A2: Contract | B2: Risk Commencement Date | C2: FY | D2: FY | E2: FY | F2: FY | G2: RCD FY | H2: Paid to date | I2: FY | J2: Orignal SA | K2: Bonus % Including Special Bonus | AK2: Bonus as per Calculator
K3: FY01 | L3: FY02 | M3: FY03 | N3: FY04 | O3: FY05 | P3: FY06 | Q3: FY07 | R3: FY08 | S3: FY09 | T3: FY10 | U3: FY11 | V3: FY12 | W3: FY13 | X3: FY14 | Y3: FY15 | Z3: FY16 | AA3: FY17 | AB3: FY18 | AC3: FY19 | AD3: FY20 | AE3: FY21 | AF3: FY22 | AG3: FY23 | AH3: FY24 | AI3: FY25 | AJ3: FY26
K4: 0 | L4: 0 | M4: 0 | N4: 0 | O4: 0.0275 | P4: 0.03 | Q4: 0.0275 | R4: 0.025 | S4: 0.02 | T4: 0.02 | U4: 0.02 | V4: 0.018 | W4: 0.018 | X4: 0.018 | Y4: 0.018 | Z4: 0.018 | AA4: 0.018 | AB4: 0.018 | AC4: 0.018 | AD4: 0.018 | AE4: 0.018 | AF4: 0.018 | AG4: 0.018 | AH4: 0.018 | AI4: 0.018 | AJ4: 0.018
A5: test1010736 | B5: =VLOOKUP(A5,'MAINCPF CPH DEP SEP END RBC CSR'!A:AF,32,0) | C5: =+IF(AND(B5>=DATE(1999,4,1),B5<=DATE(2000,3,31)),"2000",IF(AND(B5>=DATE(2000,4,1),B5<=DATE(2001,3,31)),"2001",IF(AND(B5>=DATE(2001,4,1),B5<=DATE(2002,3,31)),"2002",IF(AND(B5>=DATE(2002,4,1),B5<=DATE(2003,3,31)),"2003",IF(AND(B5>=DATE(2003,4,1),B5<=DATE(2004,3,31)),"2004",IF(AND(B5>=DATE(2004,4,1),B5<=DATE(2005,3,31)),"2005")))))) | D5: =+IF(AND(B5>=DATE(2005,4,1),B5<=DATE(2006,3,31)),"2006",IF(AND(B5>=DATE(2006,4,1),B5<=DATE(2007,3,31)),"2007",IF(AND(B5>=DATE(2007,4,1),B5<=DATE(2008,3,31)),"2008",IF(AND(B5>=DATE(2008,4,1),B5<=DATE(2009,3,31)),"2009",IF(AND(B5>=DATE(2009,4,1),B5<=DATE(2010,3,31)),"2010"))))) | E5: =+IF(AND(B5>=DATE(2010,4,1),B5<=DATE(2011,3,31)),"2011",IF(AND(B5>=DATE(2011,4,1),B5<=DATE(2012,3,31)),"2012",IF(AND(B5>=DATE(2012,4,1),B5<=DATE(2013,3,31)),"2013",IF(AND(B5>=DATE(2013,4,1),B5<=DATE(2014,3,31)),"2014",IF(AND(B5>=DATE(2014,4,1),B5<=DATE(2015,3,31)),"2015",IF(AND(B5>=DATE(2015,4,1),B5<=DATE(2016,3,31)),"2016")))))) | F5: =+IF(AND(B5>=DATE(2016,4,1),B5<=DATE(2017,3,31)),"2017",IF(AND(B5>=DATE(2017,4,1),B5<=DATE(2018,3,31)),"2018")) | G5: =+C5+D5+E5+F5 | H5: =VLOOKUP(A5,'MAINCPF CPH DEP SEP END RBC CSR'!A:AG,33,0) | I5: =IF(H5="","",IF(MONTH($H5)<=3,YEAR($H5)-1,YEAR($H5))) | J5: =VLOOKUP(A5,'MAINCPF CPH DEP SEP END RBC CSR'!A:AT,46,0) | K5: =IF(AND($G5<=K$1,$I5>=K$1),SUM($J5:J5)*K$4," ") | L5: =IF(AND($G5<=L$1,$I5>=L$1),SUM($J5:K5)*L$4," ") | M5: =IF(AND($G5<=M$1,$I5>=M$1),SUM($J5:L5)*M$4," ") | N5: =IF(AND($G5<=N$1,$I5>=N$1),SUM($J5:M5)*N$4," ") | O5: =IF(AND($G5<=O$1,$I5>=O$1),SUM($J5:N5)*O$4," ") | P5: =IF(AND($G5<=P$1,$I5>=P$1),SUM($J5:O5)*P$4," ") | Q5: =IF(AND($G5<=Q$1,$I5>=Q$1),SUM($J5:P5)*Q$4," ") | R5: =IF(AND($G5<=R$1,$I5>=R$1),SUM($J5:Q5)*R$4," ") | ... AJ5: =IF(AND($G5<=AJ$1,$I5>=AJ$1),SUM($J5:AI5)*AJ$4," ") | AK5: =+SUM(K5:AJ5)
A6: test1010739 | B6: =VLOOKUP(A6,'MAINCPF CPH DEP SEP END RBC CSR'!A:AF,32,0) | C6: =+IF(AND(B6>=DATE(1999,4,1),B6<=DATE(2000,3,31)),"2000",IF(AND(B6>=DATE(2000,4,1),B6<=DATE(2001,3,31)),"2001",IF(AND(B6>=DATE(2001,4,1),B6<=DATE(2002,3,31)),"2002",IF(AND(B6>=DATE(2002,4,1),B6<=DATE(2003,3,31)),"2003",IF(AND(B6>=DATE(2003,4,1),B6<=DATE(2004,3,31)),"2004",IF(AND(B6>=DATE(2004,4,1),B6<=DATE(2005,3,31)),"2005")))))) | D6: =+IF(AND(B6>=DATE(2005,4,1),B6<=DATE(2006,3,31)),"2006",IF(AND(B6>=DATE(2006,4,1),B6<=DATE(2007,3,31)),"2007",IF(AND(B6>=DATE(2007,4,1),B6<=DATE(2008,3,31)),"2008",IF(AND(B6>=DATE(2008,4,1),B6<=DATE(2009,3,31)),"2009",IF(AND(B6>=DATE(2009,4,1),B6<=DATE(2010,3,31)),"2010"))))) | E6: =+IF(AND(B6>=DATE(2010,4,1),B6<=DATE(2011,3,31)),"2011",IF(AND(B6>=DATE(2011,4,1),B6<=DATE(2012,3,31)),"2012",IF(AND(B6>=DATE(2012,4,1),B6<=DATE(2013,3,31)),"2013",IF(AND(B6>=DATE(2013,4,1),B6<=DATE(2014,3,31)),"2014",IF(AND(B6>=DATE(2014,4,1),B6<=DATE(2015,3,31)),"2015",IF(AND(B6>=DATE(2015,4,1),B6<=DATE(2016,3,31)),"2016")))))) | F6: =+IF(AND(B6>=DATE(2016,4,1),B6<=DATE(2017,3,31)),"2017",IF(AND(B6>=DATE(2017,4,1),B6<=DATE(2018,3,31)),"2018")) | G6: =+C6+D6+E6+F6 | H6: =VLOOKUP(A6,'MAINCPF CPH DEP SEP END RBC CSR'!A:AG,33,0) | I6: =IF(H6="","",IF(MONTH($H6)<=3,YEAR($H6)-1,YEAR($H6))) | J6: =VLOOKUP(A6,'MAINCPF CPH DEP SEP END RBC CSR'!A:AT,46,0) | K6: =IF(AND($G6<=K$1,$I6>=K$1),SUM($J6:J6)*K$4," ") | L6: =IF(AND($G6<=L$1,$I6>=L$1),SUM($J6:K6)*L$4," ") | M6: =IF(AND($G6<=M$1,$I6>=M$1),SUM($J6:L6)*M$4," ") | N6: =IF(AND($G6<=N$1,$I6>=N$1),SUM($J6:M6)*N$4," ") | O6: =IF(AND($G6<=O$1,$I6>=O$1),SUM($J6:N6)*O$4," ") | P6: =IF(AND($G6<=P$1,$I6>=P$1),SUM($J6:O6)*P$4," ") | Q6: =IF(AND($G6<=Q$1,$I6>=Q$1),SUM($J6:P6)*Q$4," ") | R6: =IF(AND($G6<=R$1,$I6>=R$1),SUM($J6:Q6)*R$4," ") | ... AJ6: =IF(AND($G6<=AJ$1,$I6>=AJ$1),SUM($J6:AI6)*AJ$4," ") | AK6: =+SUM(K6:AJ6)

Sheet SEP_BONUS CALC
A1: Not to be deleted | B1: Current year | C1: 2026 | L1: 2001 | M1: 2002 | N1: 2003 | O1: 2004 | P1: 2005 | Q1: 2006 | R1: 2007 | S1: 2008 | T1: 2009 | U1: 2010 | V1: 2011 | W1: 2012 | X1: 2013 | Y1: 2014 | Z1: 2015 | AA1: 2016 | AB1: 2017 | AC1: 2018 | AD1: 2019 | AE1: 2020 | AF1: 2021 | AG1: 2022 | AH1: 2023 | AI1: 2024 | AJ1: 2025 | AK1: 2026
A2: Contract | B2: Risk Commencement Date | C2: FY | D2: FY | E2: FY | F2: FY | G2: RCD FY | H2: Paid to date | I2: FY | J2: PTD FY Final | K2: SA | L2: Bonus % Including Special Bonus | AL2: Bonus as per calculator
L3: FY01 | M3: FY02 | N3: FY03 | O3: FY04 | P3: FY05 | Q3: FY06 | R3: FY07 | S3: FY08 | T3: FY09 | U3: FY10 | V3: FY11 | W3: FY12 | X3: FY13 | Y3: FY14 | Z3: FY15 | AA3: FY16 | AB3: FY17 | AC3: FY18 | AD3: FY19 | AE3: FY20 | AF3: FY21 | AG3: FY22 | AH3: FY23 | AI3: FY24 | AJ3: FY25 | AK3: FY26
L4: 0 | M4: 0.03 | N4: 0.035 | O4: 0.03 | P4: 0.0275 | Q4: 0.03 | R4: 0.03 | S4: 0.03 | T4: 0.026 | U4: 0.026 | V4: 0.026 | W4: 0.023 | X4: 0.023 | Y4: 0.023 | Z4: 0.021 | AA4: 0.04 | AB4: 0.04 | AC4: 0.04 | AD4: 0.04 | AE4: 0.04 | AF4: 0.04 | AG4: 0.04 | AH4: 0.04 | AI4: 0.036 | AJ4: 0.034 | AK4: 0.034
A5: test1018255 | B5: =VLOOKUP(A5,'MAINCPF CPH DEP SEP END RBC CSR'!A:AF,32,0) | C5: =+IF(AND(B5>=DATE(1999,4,1),B5<=DATE(2000,3,31)),"2000",IF(AND(B5>=DATE(2000,4,1),B5<=DATE(2001,3,31)),"2001",IF(AND(B5>=DATE(2001,4,1),B5<=DATE(2002,3,31)),"2002",IF(AND(B5>=DATE(2002,4,1),B5<=DATE(2003,3,31)),"2003",IF(AND(B5>=DATE(2003,4,1),B5<=DATE(2004,3,31)),"2004",IF(AND(B5>=DATE(2004,4,1),B5<=DATE(2005,3,31)),"2005")))))) | D5: =+IF(AND(B5>=DATE(2005,4,1),B5<=DATE(2006,3,31)),"2006",IF(AND(B5>=DATE(2006,4,1),B5<=DATE(2007,3,31)),"2007",IF(AND(B5>=DATE(2007,4,1),B5<=DATE(2008,3,31)),"2008",IF(AND(B5>=DATE(2008,4,1),B5<=DATE(2009,3,31)),"2009",IF(AND(B5>=DATE(2009,4,1),B5<=DATE(2010,3,31)),"2010"))))) | E5: =+IF(AND(B5>=DATE(2010,4,1),B5<=DATE(2011,3,31)),"2011",IF(AND(B5>=DATE(2011,4,1),B5<=DATE(2012,3,31)),"2012",IF(AND(B5>=DATE(2012,4,1),B5<=DATE(2013,3,31)),"2013",IF(AND(B5>=DATE(2013,4,1),B5<=DATE(2014,3,31)),"2014",IF(AND(B5>=DATE(2014,4,1),B5<=DATE(2015,3,31)),"2015",IF(AND(B5>=DATE(2015,4,1),B5<=DATE(2016,3,31)),"2016")))))) | F5: =+IF(AND(B5>=DATE(2016,4,1),B5<=DATE(2017,3,31)),"2017",IF(AND(B5>=DATE(2017,4,1),B5<=DATE(2018,3,31)),"2018")) | G5: =+C5+D5+E5+F5 | H5: =VLOOKUP(A5,'MAINCPF CPH DEP SEP END RBC CSR'!A:AG,33,0) | I5: =IF(H5="","",IF(MONTH($H5)<=3,YEAR($H5)-1,YEAR($H5))) | J5: =IF(H5="","",IF($I5+5=$C$1,$C$1,$I5)) | K5: =VLOOKUP(A5,'MAINCPF CPH DEP SEP END RBC CSR'!A:AT,46,0) | L5: =IF(AND($G5<=L$1,$J5>=L$1),SUM($K5:K5)*L$4," ") | M5: =IF(AND($G5<=M$1,$J5>=M$1),SUM($K5:L5)*M$4," ") | N5: =IF(AND($G5<=N$1,$J5>=N$1),SUM($K5:M5)*N$4," ") | O5: =IF(AND($G5<=O$1,$J5>=O$1),SUM($K5:N5)*O$4," ") | P5: =IF(AND($G5<=P$1,$J5>=P$1),SUM($K5:O5)*P$4," ") | Q5: =IF(AND($G5<=Q$1,$J5>=Q$1),SUM($K5:P5)*Q$4," ") | R5: =IF(AND($G5<=R$1,$J5>=R$1),SUM($K5:Q5)*R$4," ") | S5: =IF(AND($G5<=S$1,$J5>=S$1),SUM($K5:R5)*S$4," ") | ... AK5: =IF(AND($G5<=AK$1,$J5>=AK$1),SUM($K5:AJ5)*AK$4," ") | AL5: =+SUM(L5:AK5)
AN76: 15
AN77: =SUM(P77:AD77)

Sheet END_BONUS CALC
A1: Not to be deleted | B1: Current year | C1: 2026 | F1: 1 | K1: 2001 | L1: 2002 | M1: 2003 | N1: 2004 | O1: 2005 | P1: 2006 | Q1: 2007 | R1: 2008 | S1: 2009 | T1: 2010 | U1: 2011 | V1: 2012 | W1: 2013 | X1: 2014 | Y1: 2015 | Z1: 2016 | AA1: 2017 | AB1: 2018 | AC1: 2019 | AD1: 2020 | AE1: 2021 | AF1: 2022 | AG1: 2023 | AH1: 2024 | AI1: 2025 | AJ1: 2026
A2: Contract | B2: Risk Commencement Date | C2: FY | D2: FY | E2: FY | F2: FY | G2: RCD FY | H2: Paid to date | I2: PTD FY | J2: Original SA | K2: Bonus % Including Special Bonus | AK2: Bonus as per calculator
K3: FY01 | L3: FY02 | M3: FY03 | N3: FY04 | O3: FY05 | P3: FY06 | Q3: FY07 | R3: FY08 | S3: FY09 | T3: FY10 | U3: FY11 | V3: FY12 | W3: FY13 | X3: FY14 | Y3: FY15 | Z3: FY16 | AA3: FY17 | AB3: FY18 | AC3: FY19 | AD3: FY20 | AE3: FY21 | AF3: FY22 | AG3: FY23 | AH3: FY24 | AI3: FY25 | AJ3: FY26
K5: 0 | L5: 0 | M5: 0 | N5: 0 | O5: 0 | P5: 0 | Q5: 0 | R5: 0 | S5: 0 | T5: 0 | U5: 0 | V5: 0 | W5: 0.018 | X5: 0.0125 | Y5: 0.018 | Z5: 0.02 | AA5: 0.02 | AB5: 0.02 | AC5: 0.02 | AD5: 0.02 | AE5: 0.02 | AF5: 0.02 | AG5: 0.02 | AH5: 0.02 | AI5: 0.02 | AJ5: 0.02
A6: test5261716 | B6: =VLOOKUP(A6,'MAINCPF CPH DEP SEP END RBC CSR'!$A:$AF,32,0) | C6: =+IF(AND(B6>=DATE(1999,4,1),B6<=DATE(2000,3,31)),"2000",IF(AND(B6>=DATE(2000,4,1),B6<=DATE(2001,3,31)),"2001",IF(AND(B6>=DATE(2001,4,1),B6<=DATE(2002,3,31)),"2002",IF(AND(B6>=DATE(2002,4,1),B6<=DATE(2003,3,31)),"2003",IF(AND(B6>=DATE(2003,4,1),B6<=DATE(2004,3,31)),"2004",IF(AND(B6>=DATE(2004,4,1),B6<=DATE(2005,3,31)),"2005")))))) | D6: =+IF(AND(B6>=DATE(2005,4,1),B6<=DATE(2006,3,31)),"2006",IF(AND(B6>=DATE(2006,4,1),B6<=DATE(2007,3,31)),"2007",IF(AND(B6>=DATE(2007,4,1),B6<=DATE(2008,3,31)),"2008",IF(AND(B6>=DATE(2008,4,1),B6<=DATE(2009,3,31)),"2009",IF(AND(B6>=DATE(2009,4,1),B6<=DATE(2010,3,31)),"2010"))))) | E6: =+IF(AND(B6>=DATE(2010,4,1),B6<=DATE(2011,3,31)),"2011",IF(AND(B6>=DATE(2011,4,1),B6<=DATE(2012,3,31)),"2012",IF(AND(B6>=DATE(2012,4,1),B6<=DATE(2013,3,31)),"2013",IF(AND(B6>=DATE(2013,4,1),B6<=DATE(2014,3,31)),"2014",IF(AND(B6>=DATE(2014,4,1),B6<=DATE(2015,3,31)),"2015",IF(AND(B6>=DATE(2015,4,1),B6<=DATE(2016,3,31)),"2016")))))) | F6: =+IF(AND(B6>=DATE(2016,4,1),B6<=DATE(2017,3,31)),"2017",IF(AND(B6>=DATE(2017,4,1),B6<=DATE(2018,3,31)),"2018")) | G6: =+C6+D6+E6+F6 | H6: =VLOOKUP(A6,'MAINCPF CPH DEP SEP END RBC CSR'!$A:$AG,33,0) | I6: =IF(H6="","",IF(MONTH($H6)<=3,YEAR($H6)-1,YEAR($H6))) | J6: =VLOOKUP(A6,'MAINCPF CPH DEP SEP END RBC CSR'!A:AT,46,0) | K6: =IF(AND($G6<=K$1,$I6>=K$1),SUM($J6:J6)*K$5," ") | L6: =IF(AND($G6<=L$1,$I6>=L$1),SUM($J6:K6)*L$5," ") | M6: =IF(AND($G6<=M$1,$I6>=M$1),SUM($J6:L6)*M$5," ") | N6: =IF(AND($G6<=N$1,$I6>=N$1),SUM($J6:M6)*N$5," ") | O6: =IF(AND($G6<=O$1,$I6>=O$1),SUM($J6:N6)*O$5," ") | P6: =IF(AND($G6<=P$1,$I6>=P$1),SUM($J6:O6)*P$5," ") | Q6: =IF(AND($G6<=Q$1,$I6>=Q$1),SUM($J6:P6)*Q$5," ") | R6: =IF(AND($G6<=R$1,$I6>=R$1),SUM($J6:Q6)*R$5," ") | ... AJ6: =IF(AND($G6<=AJ$1,$I6>=AJ$1),SUM($J6:AI6)*AJ$5," ") | AK6: =SUM(K6:AJ6)
A7: test5262934 | B7: =VLOOKUP(A7,'MAINCPF CPH DEP SEP END RBC CSR'!$A:$AF,32,0) | C7: =+IF(AND(B7>=DATE(1999,4,1),B7<=DATE(2000,3,31)),"2000",IF(AND(B7>=DATE(2000,4,1),B7<=DATE(2001,3,31)),"2001",IF(AND(B7>=DATE(2001,4,1),B7<=DATE(2002,3,31)),"2002",IF(AND(B7>=DATE(2002,4,1),B7<=DATE(2003,3,31)),"2003",IF(AND(B7>=DATE(2003,4,1),B7<=DATE(2004,3,31)),"2004",IF(AND(B7>=DATE(2004,4,1),B7<=DATE(2005,3,31)),"2005")))))) | D7: =+IF(AND(B7>=DATE(2005,4,1),B7<=DATE(2006,3,31)),"2006",IF(AND(B7>=DATE(2006,4,1),B7<=DATE(2007,3,31)),"2007",IF(AND(B7>=DATE(2007,4,1),B7<=DATE(2008,3,31)),"2008",IF(AND(B7>=DATE(2008,4,1),B7<=DATE(2009,3,31)),"2009",IF(AND(B7>=DATE(2009,4,1),B7<=DATE(2010,3,31)),"2010"))))) | E7: =+IF(AND(B7>=DATE(2010,4,1),B7<=DATE(2011,3,31)),"2011",IF(AND(B7>=DATE(2011,4,1),B7<=DATE(2012,3,31)),"2012",IF(AND(B7>=DATE(2012,4,1),B7<=DATE(2013,3,31)),"2013",IF(AND(B7>=DATE(2013,4,1),B7<=DATE(2014,3,31)),"2014",IF(AND(B7>=DATE(2014,4,1),B7<=DATE(2015,3,31)),"2015",IF(AND(B7>=DATE(2015,4,1),B7<=DATE(2016,3,31)),"2016")))))) | F7: =+IF(AND(B7>=DATE(2016,4,1),B7<=DATE(2017,3,31)),"2017",IF(AND(B7>=DATE(2017,4,1),B7<=DATE(2018,3,31)),"2018")) | G7: =+C7+D7+E7+F7 | H7: =VLOOKUP(A7,'MAINCPF CPH DEP SEP END RBC CSR'!$A:$AG,33,0) | I7: =IF(H7="","",IF(MONTH($H7)<=3,YEAR($H7)-1,YEAR($H7))) | J7: =VLOOKUP(A7,'MAINCPF CPH DEP SEP END RBC CSR'!A:AT,46,0) | K7: =IF(AND($G7<=K$1,$I7>=K$1),SUM($J7:J7)*K$5," ") | L7: =IF(AND($G7<=L$1,$I7>=L$1),SUM($J7:K7)*L$5," ") | M7: =IF(AND($G7<=M$1,$I7>=M$1),SUM($J7:L7)*M$5," ") | N7: =IF(AND($G7<=N$1,$I7>=N$1),SUM($J7:M7)*N$5," ") | O7: =IF(AND($G7<=O$1,$I7>=O$1),SUM($J7:N7)*O$5," ") | P7: =IF(AND($G7<=P$1,$I7>=P$1),SUM($J7:O7)*P$5," ") | Q7: =IF(AND($G7<=Q$1,$I7>=Q$1),SUM($J7:P7)*Q$5," ") | R7: =IF(AND($G7<=R$1,$I7>=R$1),SUM($J7:Q7)*R$5," ") | ... AJ7: =IF(AND($G7<=AJ$1,$I7>=AJ$1),SUM($J7:AI7)*AJ$5," ") | AK7: =SUM(K7:AJ7)

Sheet RBC_BONUS CALC
A1: Current year | B1: 2026 | J1: Not to be deleted | L1: 2001 | M1: 2002 | N1: 2003 | O1: 2004 | P1: 2005 | Q1: 2006 | R1: 2007 | S1: 2008 | T1: 2009 | U1: 2010 | V1: 2011 | W1: 2012 | X1: 2013 | Y1: 2014 | Z1: 2015 | AA1: 2016 | AB1: 2017 | AC1: 2018 | AD1: 2019 | AE1: 2020 | AF1: 2021 | AG1: 2022 | AH1: 2023 | AI1: 2024 | AJ1: 2025 | AK1: 2026
A2: Contract | B2: Risk Commencement Date | C2: FY | D2: FY | E2: FY | F2: FY | G2: RCD FY | H2: POLICY STATUS | I2: Risk Cess Date (Inforce) & PTD (Paidup) | J2: FY | K2: Original SA | L2: Bonus % Including Special Bonus | AL2: Bonus as per Calculator
L3: FY01 | M3: FY02 | N3: FY03 | O3: FY04 | P3: FY05 | Q3: FY06 | R3: FY07 | S3: FY08 | T3: FY09 | U3: FY10 | V3: FY11 | W3: FY12 | X3: FY13 | Y3: FY14 | Z3: FY15 | AA3: FY16 | AB3: FY17 | AC3: FY18 | AD3: FY19 | AE3: FY20 | AF3: FY21 | AG3: FY22 | AH3: FY23 | AI3: FY24 | AJ3: FY25 | AK3: FY26
L4: 0 | Z4: 0.04 | AA4: 0.055 | AB4: 0.055 | AC4: 0.055 | AD4: 0.055 | AE4: 0.055 | AF4: 0.055 | AG4: 0.055 | AH4: 0.055 | AI4: 0.055 | AJ4: 0.055 | AK4: 0.055
A5: test5263254 | B5: =VLOOKUP(A5,'MAINCPF CPH DEP SEP END RBC CSR'!A:AT,32,0) | C5: =+IF(AND(B5>=DATE(1999,4,1),B5<=DATE(2000,3,31)),"2000",IF(AND(B5>=DATE(2000,4,1),B5<=DATE(2001,3,31)),"2001",IF(AND(B5>=DATE(2001,4,1),B5<=DATE(2002,3,31)),"2002",IF(AND(B5>=DATE(2002,4,1),B5<=DATE(2003,3,31)),"2003",IF(AND(B5>=DATE(2003,4,1),B5<=DATE(2004,3,31)),"2004",IF(AND(B5>=DATE(2004,4,1),B5<=DATE(2005,3,31)),"2005")))))) | D5: =+IF(AND(B5>=DATE(2005,4,1),B5<=DATE(2006,3,31)),"2006",IF(AND(B5>=DATE(2006,4,1),B5<=DATE(2007,3,31)),"2007",IF(AND(B5>=DATE(2007,4,1),B5<=DATE(2008,3,31)),"2008",IF(AND(B5>=DATE(2008,4,1),B5<=DATE(2009,3,31)),"2009",IF(AND(B5>=DATE(2009,4,1),B5<=DATE(2010,3,31)),"2010"))))) | E5: =+IF(AND(B5>=DATE(2010,4,1),B5<=DATE(2011,3,31)),"2011",IF(AND(B5>=DATE(2011,4,1),B5<=DATE(2012,3,31)),"2012",IF(AND(B5>=DATE(2012,4,1),B5<=DATE(2013,3,31)),"2013",IF(AND(B5>=DATE(2013,4,1),B5<=DATE(2014,3,31)),"2014",IF(AND(B5>=DATE(2014,4,1),B5<=DATE(2015,3,31)),"2015",IF(AND(B5>=DATE(2015,4,1),B5<=DATE(2016,3,31)),"2016")))))) | F5: =+IF(AND(B5>=DATE(2016,4,1),B5<=DATE(2017,3,31)),"2017",IF(AND(B5>=DATE(2017,4,1),B5<=DATE(2018,3,31)),"2018")) | G5: =+C5+D5+E5+F5 | H5: =VLOOKUP(A5,'MAINCPF CPH DEP SEP END RBC CSR'!A:B,2,0) | I5: =IF(H5="if",VLOOKUP(A5,'MAINCPF CPH DEP SEP END RBC CSR'!A:AH,34,0),(VLOOKUP(A5,'MAINCPF CPH DEP SEP END RBC CSR'!A:AG,33,0))) | J5: =IF(I5="","",IF(MONTH($I5)<=3,YEAR($I5)-1,YEAR($I5))) | K5: =VLOOKUP(A5,'MAINCPF CPH DEP SEP END RBC CSR'!A:AT,46,0) | L5: =IF(AND($G5<=L$1,$J5>=L$1),$K5*L$4," ") | M5: =IF(AND($G5<=M$1,$J5>=M$1),$K5*M$4," ") | N5: =IF(AND($G5<=N$1,$J5>=N$1),$K5*N$4," ") | O5: =IF(AND($G5<=O$1,$J5>=O$1),$K5*O$4," ") | P5: =IF(AND($G5<=P$1,$J5>=P$1),$K5*P$4," ") | Q5: =IF(AND($G5<=Q$1,$J5>=Q$1),$K5*Q$4," ") | R5: =IF(AND($G5<=R$1,$J5>=R$1),$K5*R$4," ") | S5: =IF(AND($G5<=S$1,$J5>=S$1),$K5*S$4," ") | ... AK5: =IF(AND($G5<=AK$1,$J5>=AK$1),$K5*AK$4," ") | AL5: =+SUM(L5:AK5)
